Workbook

Sheet ReadMe
A1: Финансовая модель — Promo Automation (Efes Kazakhstan)
A3: Назначение | B3: Внутренний бизнес-кейс (ROI) платформы автоматизации промо-активностей и компенсаций. Не модель выручки: считаются реальная экономия и снятые риски, а не рыночные оценки.
A4: Логика | B4: Inputs (Вводные) → 3 расчётных листа по сценариям (Calc_Pess / Calc_Base / Calc_Opt) → Annual_Summary (активный) → Scenario_Compare → Dashboard. Model_Check — аудит. Sources — источники.
A5: Как пользоваться | B5: Редактируйте только цветные ячейки на листе Inputs. Переключатель «Активный сценарий» (Inputs!B4) меняет, какой сценарий показывают Annual_Summary и Dashboard. Каждый сценарий настраивается отдельно своими колонками.
A6: Сценарии | B6: Пессимистичный / Реалистичный / Оптимистичный — независимые наборы допущений (часы, база компенсаций, доля ошибок, затраты, скорость адаптии). Все три считаются всегда; сравнение — на листе Scenario_Compare.
A7: Охват | B7: Автоматизируются ТОЛЬКО промо-активности (N+1, кешбэк). Цикл компенсаций операторов и техников исключён из охвата.
A8: Выгоды | B8: (1) Экономия труда = число специалистов (5) × рабочих часов специалиста/мес (140) × доля автоматизации (≈35%) × стоимость часа × адаптия. Сэконом. часы постоянны по годам, разные по сценариям. (2) Снятый риск (прямые потери) = база × доля ошибок в ручной обработке (1%) × доля НЕВЫЯВЛЕННЫХ ошибок (Пессим 3% / Реалист 5% / Оптим 7%). Невыявленные = прямой невозвратный убыток (выявленные исправляются без потерь). Реалист.: труд ≈ ₸16,8 млн/год; риск растёт с базой (≈₸1,7→₸3,7 млн/год).
A9: Рост базы | B9: База компенсаций по промо берётся от факта 2025 (₸2,41 млрд; факт 2024 = ₸1,42 млрд, рост ≈ +69%) и растёт по сценарному годовому темпу (Пессим 30% / Реалист 45% / Оптим 65%). База по годам = (факт 2025) × (1+темп)^год. Факт 2025 и темпы редактируются на листе Inputs.
A10: Затраты | B10: Разовая разработка ₸5 млн (единая для всех сценариев) списывается в Месяц 1. Опер. расходы (хостинг, AI, поддержка ≈₸6 млн/год реалист.) — с месяца go-live.
A11: Адаптия | B11: Выгоды набираются линейно от go-live до 100% за заданное число месяцев (реалист. 6). Поэтому реализованная выгода Года 1 < годового run-rate.
A12: Налоги | B12: Чистая выгода увеличивает прибыль и облагается КПН 20% (настраивается) с помесячным переносом убытка (разработка Месяца 1 создаёт щит).
A13: Окупаемость | B13: NPV и дисконт. окупаемость считаются по месячным денежным потокам при годовой ставке дисконтирования (Inputs!B10, по умолч. 15%). IRR при крошечных вложениях очень велик — ориентируйтесь на NPV, ROI и срок окупаемости.
A14: Цвета | B14: Синий шрифт на янтарном фоне = редактируемая вводная; чёрный = формула; зелёный = ссылка на другой лист.
A15: Оговорки | B15: Рост базы компенсаций по промо (Год 2–3) опирается на рост охвата (партнёры, SKU, точки) из презентации. «Всего часов на промо», доля автоматизации (35%) и доля ошибок (0,3%) — допущения; проверьте по факту. Стресс-тест — сценарий «Пессимистичный».

Sheet Inputs
A1: Promo Automation — финансовая модель (Efes Kazakhstan) · внутренний бизнес-кейс · KZT
A2: Единый источник допущений. Редактируйте только ЦВЕТНЫЕ (синие на янтарном фоне) ячейки. Чёрный = формула, зелёный = ссылка на другой лист.
A3: ПЕРЕКЛЮЧАТЕЛЬ СЦЕНАРИЯ
A4: Активный сценарий | B4: Реалистичный | D4: ← выберите: Пессимистичный / Реалистичный / Оптимистичный
A5: → индекс активного сценария | B5: =MATCH(B4,C5:E5,0) -> 2 | C5: Пессимистичный | D5: Реалистичный | E5: Оптимистичный
A7: ГЛОБАЛЬНЫЕ ПАРАМЕТРЫ (едины для всех сценариев)
A8: Дата старта (Месяц 1) | B8: 46174 | C8: дата | O8: Месяц 1 = старт проекта
A9: Месяц выхода в эксплуатацию (go-live) | B9: 2 | C9: № мес | O9: Разработка — Месяц 1; выгоды и опер. расходы — с этого месяца
A10: Ставка дисконтирования (годовая) | B10: 0.15 | C10: % / год | O10: Для NPV / дисконт. окупаемости
A11: Ставка налога на прибыль (КПН) | B11: 0.2 | C11: % | O11: КПН РК; с переносом убытка
A12: Загруженная стоимость часа | B12: 5714 | C12: ₸ / ч | O12: Источник: презентация (₸5 714/ч)
A13: Рабочих часов специалиста в месяц | B13: 140 | C13: ч/мес | O13: Общая месячная загрузка одного специалиста
A14: Число специалистов (промо) | B14: 5 | C14: чел. | O14: Чьё промо-время автоматизирует система. Сэконом. часы = число × часы × доля автоматизации
A15: База компенсаций по промо — 2024 (факт) | B15: 1.4247165e+09 | C15: ₸ | O15: Факт: компенсации по промо-активностям за 2024 г.
A16: База компенсаций по промо — 2025 (факт, база отсчёта) | B16: 2.4071211e+09 | C16: ₸ | O16: Факт за 2025 г.; от него растёт база по годам модели
A17: Историч. рост базы 2024→2025 (справочно) | B17: =B16/B15-1 -> 0.68954394 | C17: %/год | O17: ≈ +69%; ориентир для сценарных темпов роста ниже
A18: Доля ошибок в ручной обработке (стабильно) | B18: 0.01 | C18: % базы | O18: 1% — расчётная доля ошибок в ручной обработке промо-компенсаций; стабильна по сценариям. Часть из них уходит без детекции (см. ниже)
A19: ДОПУЩЕНИЯ ПО СЦЕНАРИЯМ (каждый сценарий настраивается отдельно)
C20: ПЕССИМИСТИЧНЫЙ | F20: РЕАЛИСТИЧНЫЙ | I20: ОПТИМИСТИЧНЫЙ | L20: АКТИВНЫЙ (по переключателю)
A21: Показатель | B21: Ед. | C21: Год 1 | D21: Год 2 | E21: Год 3 | F21: Год 1 | G21: Год 2 | H21: Год 3 | I21: Год 1 | J21: Год 2 | K21: Год 3 | L21: Год 1 | M21: Год 2 | N21: Год 3 | O21: Примечание
A22: ВЫГОДЫ — ЭКОНОМИЯ РАБОЧЕГО ВРЕМЕНИ (промо-активности)
A23: Доля автоматизируемого времени | B23: % времени | C23: 0.3 | F23: 0.35 | I23: 0.4 | L23: =CHOOSE($B$5,C23,F23,I23) -> 0.35 | O23: ≈35% общего времени специалиста автоматизируется (реалист.). Сэконом. часы = число спец. × часы спец. × эта доля — постоянны по годам, разные по сценариям
A24: ВЫГОДЫ — СНИЖЕНИЕ РИСКА ОШИБОК (по промо-активностям)
A25: Годовой рост базы компенсаций | B25: %/год | C25: 0.3 | F25: 0.45 | I25: 0.65 | L25: =CHOOSE($B$5,C25,F25,I25) -> 0.45 | O25: Темп роста базы компенсаций по промо, свой для каждого сценария. Историч. 2024→2025 ≈ +69% (см. глоб. параметры)
A26: База компенсаций по промо в год (расчёт) | B26: ₸/год | C26: =$B$16*(1+C25)^1 -> 3.1292574e+09 | D26: =$B$16*(1+C25)^2 -> 4.0680347e+09 | E26: =$B$16*(1+C25)^3 -> 5.2884451e+09 | F26: =$B$16*(1+F25)^1 -> 3.4903256e+09 | G26: =$B$16*(1+F25)^2 -> 5.0609721e+09 | H26: =$B$16*(1+F25)^3 -> 7.3384096e+09 | I26: =$B$16*(1+I25)^1 -> 3.9717498e+09 | J26: =$B$16*(1+I25)^2 -> 6.5533872e+09 | K26: =$B$16*(1+I25)^3 -> 1.0813089e+10 | L26: =CHOOSE($B$5,C26,F26,I26) -> 3.4903256e+09 | M26: =CHOOSE($B$5,D26,G26,J26) -> 5.0609721e+09 | N26: =CHOOSE($B$5,E26,H26,K26) -> 7.3384096e+09 | O26: Расчёт: факт 2025 × (1+рост)^год. Различие сценариев — через темп роста
A27: Доля невыявленных ошибок (прямой убыток) | B27: % от ошибок | C27: 0.03 | D27: 0.03 | E27: 0.03 | F27: 0.05 | G27: 0.05 | H27: 0.05 | I27: 0.07 | J27: 0.07 | K27: 0.07 | L27: =CHOOSE($B$5,C27,F27,I27) -> 0.05 | M27: =CHOOSE($B$5,D27,G27,J27) -> 0.05 | N27: =CHOOSE($B$5,E27,H27,K27) -> 0.05 | O27: Доля ошибок, которые прошли мимо ручного контроля — это прямой невозвратный убыток (выявленные ошибки исправляются, без убытка). Сценарии Пессим/Реалист/Оптим = 3%/5%/7%. Прямой убыток = база × доля ошибок (1%) × эта доля
A28: ЗАТРАТЫ
A29: Стоимость разработки (разовая, Месяц 1) | B29: ₸ | C29: 5000000 | F29: 5000000 | I29: 5000000 | L29: =CHOOSE($B$5,C29,F29,I29) -> 5000000 | O29: Списывается в Месяц 1. ₸5 млн — единая стоимость во всех сценариях (по указанию пользователя)
A30: Опер. расходы (хостинг, AI, поддержка) | B30: ₸/мес | C30: 600000 | D30: 640000 | E30: 690000 | F30: 500000 | G30: 520000 | H30: 550000 | I30: 450000 | J30: 460000 | K30: 480000 | L30: =CHOOSE($B$5,C30,F30,I30) -> 500000 | M30: =CHOOSE($B$5,D30,G30,J30) -> 520000 | N30: =CHOOSE($B$5,E30,H30,K30) -> 550000 | O30: Реалист. ≈ ₸6 млн/год. Начинаются с go-live
A31: ВНЕДРЕНИЕ / АДАПТАЦИЯ
A32: Выход на полную отдачу за | B32: мес | C32: 9 | F32: 6 | I32: 3 | L32: =CHOOSE($B$5,C32,F32,I32) -> 6 | O32: Линейный набор выгод от go-live до 100%
A34: Логика: выгоды (экономия труда + снятый риск ошибок) набираются по кривой адаптии с момента go-live; база компенсаций растёт от факта 2025 по сценарному темпу; затраты = разовая разработка (Месяц 1) + опер. расходы. Чистая выгода облагается КПН (с переносом убытка). См. лист ReadMe.

Sheet Calc_Pess
A1: Расчёт · ПЕССИМИСТИЧНЫЙ сценарий
A2: Помесячный расчёт (36 мес). Денежные суммы — в ₸ (точные). Читает только колонки своего сценария с листа Inputs.
A3: № мес | B3: Дата | C3: Год | D3: Мес в году | E3: Адаптация | F3: Сэкон. часов/мес | G3: Экономия труда | H3: База компенсаций | I3: Доля невыявл. ошибок | J3: Экономия от риска | K3: Итого выгоды | L3: Разработка | M3: Опер. расходы | N3: Итого затраты | O3: Прибыль до налога | P3: Перенос убытка (вх.) | Q3: Налогооблагаемая | R3: Перенос убытка (исх.) | S3: Налог КПН | T3: Чистая выгода | U3: Накопл. чистая выгода | V3: Дисконт-фактор | W3: Дисконт. выгода | X3: Накопл. дисконт. выгода | Y3: Окупаемость (флаг) | Z3: Дисконт. окуп. (флаг)
A4: 1 | B4: =EDATE(Inputs!$B$8,A4-1) -> 46174 | C4: =ROUNDUP(A4/12,0) -> 1 | D4: =MOD(A4-1,12)+1 -> 1 | E4: =IF(A4<Inputs!$B$9,0,MIN(1,(A4-Inputs!$B$9+1)/Inputs!$C$32)) -> 0 | F4: =Inputs!$B$14*Inputs!$B$13*Inputs!$C$23 -> 210 | G4: =F4*Inputs!$B$12*E4 -> 0 | H4: =INDEX(Inputs!$C$26:$E$26,1,C4) -> 3.1292574e+09 | I4: =INDEX(Inputs!$C$27:$E$27,1,C4) -> 0.03 | J4: =H4*Inputs!$B$18*I4/12*E4 -> 0 | K4: =G4+J4 -> 0 | L4: =IF(A4=1,Inputs!$C$29,0) -> 5000000 | M4: =IF(A4>=Inputs!$B$9,INDEX(Inputs!$C$30:$E$30,1,C4),0) -> 0 | N4: =L4+M4 -> 5000000 | O4: =K4-N4 -> -5000000 | P4: =0 -> 0 | Q4: =MAX(O4-P4,0) -> 0 | R4: =MAX(P4-O4,0) -> 5000000 | S4: =Q4*Inputs!$B$11 -> 0 | T4: =O4-S4 -> -5000000 | U4: =T4 -> -5000000 | V4: =1/(1+Inputs!$B$10)^(A4/12) -> 0.98842073 | W4: =T4*V4 -> -4942103.7 | X4: =W4 -> -4942103.7 | Y4: =IF(U4>=0,A4,"") | Z4: =IF(X4>=0,A4,"")
A5: 2 | B5: =EDATE(Inputs!$B$8,A5-1) -> 46204 | C5: =ROUNDUP(A5/12,0) -> 1 | D5: =MOD(A5-1,12)+1 -> 2 | E5: =IF(A5<Inputs!$B$9,0,MIN(1,(A5-Inputs!$B$9+1)/Inputs!$C$32)) -> 0.11111111 | F5: =Inputs!$B$14*Inputs!$B$13*Inputs!$C$23 -> 210 | G5: =F5*Inputs!$B$12*E5 -> 133326.67 | H5: =INDEX(Inputs!$C$26:$E$26,1,C5) -> 3.1292574e+09 | I5: =INDEX(Inputs!$C$27:$E$27,1,C5) -> 0.03 | J5: =H5*Inputs!$B$18*I5/12*E5 -> 8692.3818 | K5: =G5+J5 -> 142019.05 | L5: =IF(A5=1,Inputs!$C$29,0) -> 0 | M5: =IF(A5>=Inputs!$B$9,INDEX(Inputs!$C$30:$E$30,1,C5),0) -> 600000 | N5: =L5+M5 -> 600000 | O5: =K5-N5 -> -457980.95 | P5: =R4 -> 5000000 | Q5: =MAX(O5-P5,0) -> 0 | R5: =MAX(P5-O5,0) -> 5457981 | S5: =Q5*Inputs!$B$11 -> 0 | T5: =O5-S5 -> -457980.95 | U5: =U4+T5 -> -5457981 | V5: =1/(1+Inputs!$B$10)^(A5/12) -> 0.97697555 | W5: =T5*V5 -> -447436.19 | X5: =X4+W5 -> -5389539.9 | Y5: =IF(U5>=0,A5,"") | Z5: =IF(X5>=0,A5,"")
A6: 3 | B6: =EDATE(Inputs!$B$8,A6-1) -> 46235 | C6: =ROUNDUP(A6/12,0) -> 1 | D6: =MOD(A6-1,12)+1 -> 3 | E6: =IF(A6<Inputs!$B$9,0,MIN(1,(A6-Inputs!$B$9+1)/Inputs!$C$32)) -> 0.22222222 | F6: =Inputs!$B$14*Inputs!$B$13*Inputs!$C$23 -> 210 | G6: =F6*Inputs!$B$12*E6 -> 266653.33 | H6: =INDEX(Inputs!$C$26:$E$26,1,C6) -> 3.1292574e+09 | I6: =INDEX(Inputs!$C$27:$E$27,1,C6) -> 0.03 | J6: =H6*Inputs!$B$18*I6/12*E6 -> 17384.764 | K6: =G6+J6 -> 284038.1 | L6: =IF(A6=1,Inputs!$C$29,0) -> 0 | M6: =IF(A6>=Inputs!$B$9,INDEX(Inputs!$C$30:$E$30,1,C6),0) -> 600000 | N6: =L6+M6 -> 600000 | O6: =K6-N6 -> -315961.9 | P6: =R5 -> 5457981 | Q6: =MAX(O6-P6,0) -> 0 | R6: =MAX(P6-O6,0) -> 5773942.9 | S6: =Q6*Inputs!$B$11 -> 0 | T6: =O6-S6 -> -315961.9 | U6: =U5+T6 -> -5773942.9 | V6: =1/(1+Inputs!$B$10)^(A6/12) -> 0.96566289 | W6: =T6*V6 -> -305112.68 | X6: =X5+W6 -> -5694652.5 | Y6: =IF(U6>=0,A6,"") | Z6: =IF(X6>=0,A6,"")
A7: 4 | B7: =EDATE(Inputs!$B$8,A7-1) -> 46266 | C7: =ROUNDUP(A7/12,0) -> 1 | D7: =MOD(A7-1,12)+1 -> 4 | E7: =IF(A7<Inputs!$B$9,0,MIN(1,(A7-Inputs!$B$9+1)/Inputs!$C$32)) -> 0.33333333 | F7: =Inputs!$B$14*Inputs!$B$13*Inputs!$C$23 -> 210 | G7: =F7*Inputs!$B$12*E7 -> 399980 | H7: =INDEX(Inputs!$C$26:$E$26,1,C7) -> 3.1292574e+09 | I7: =INDEX(Inputs!$C$27:$E$27,1,C7) -> 0.03 | J7: =H7*Inputs!$B$18*I7/12*E7 -> 26077.145 | K7: =G7+J7 -> 426057.15 | L7: =IF(A7=1,Inputs!$C$29,0) -> 0 | M7: =IF(A7>=Inputs!$B$9,INDEX(Inputs!$C$30:$E$30,1,C7),0) -> 600000 | N7: =L7+M7 -> 600000 | O7: =K7-N7 -> -173942.85 | P7: =R6 -> 5773942.9 | Q7: =MAX(O7-P7,0) -> 0 | R7: =MAX(P7-O7,0) -> 5947885.7 | S7: =Q7*Inputs!$B$11 -> 0 | T7: =O7-S7 -> -173942.85 | U7: =U6+T7 -> -5947885.7 | V7: =1/(1+Inputs!$B$10)^(A7/12) -> 0.95448122 | W7: =T7*V7 -> -166025.19 | X7: =X6+W7 -> -5860677.7 | Y7: =IF(U7>=0,A7,"") | Z7: =IF(X7>=0,A7,"")
A8: 5 | B8: =EDATE(Inputs!$B$8,A8-1) -> 46296 | C8: =ROUNDUP(A8/12,0) -> 1 | D8: =MOD(A8-1,12)+1 -> 5 | E8: =IF(A8<Inputs!$B$9,0,MIN(1,(A8-Inputs!$B$9+1)/Inputs!$C$32)) -> 0.44444444 | F8: =Inputs!$B$14*Inputs!$B$13*Inputs!$C$23 -> 210 | G8: =F8*Inputs!$B$12*E8 -> 533306.67 | H8: =INDEX(Inputs!$C$26:$E$26,1,C8) -> 3.1292574e+09 | I8: =INDEX(Inputs!$C$27:$E$27,1,C8) -> 0.03 | J8: =H8*Inputs!$B$18*I8/12*E8 -> 34769.527 | K8: =G8+J8 -> 568076.19 | L8: =IF(A8=1,Inputs!$C$29,0) -> 0 | M8: =IF(A8>=Inputs!$B$9,INDEX(Inputs!$C$30:$E$30,1,C8),0) -> 600000 | N8: =L8+M8 -> 600000 | O8: =K8-N8 -> -31923.806 | P8: =R7 -> 5947885.7 | Q8: =MAX(O8-P8,0) -> 0 | R8: =MAX(P8-O8,0) -> 5979809.5 | S8: =Q8*Inputs!$B$11 -> 0 | T8: =O8-S8 -> -31923.806 | U8: =U7+T8 -> -5979809.5 | V8: =1/(1+Inputs!$B$10)^(A8/12) -> 0.94342902 | W8: =T8*V8 -> -30117.845 | X8: =X7+W8 -> -5890795.6 | Y8: =IF(U8>=0,A8,"") | Z8: =IF(X8>=0,A8,"")
A9: 6 | B9: =EDATE(Inputs!$B$8,A9-1) -> 46327 | C9: =ROUNDUP(A9/12,0) -> 1 | D9: =MOD(A9-1,12)+1 -> 6 | E9: =IF(A9<Inputs!$B$9,0,MIN(1,(A9-Inputs!$B$9+1)/Inputs!$C$32)) -> 0.55555556 | F9: =Inputs!$B$14*Inputs!$B$13*Inputs!$C$23 -> 210 | G9: =F9*Inputs!$B$12*E9 -> 666633.33 | H9: =INDEX(Inputs!$C$26:$E$26,1,C9) -> 3.1292574e+09 | I9: =INDEX(Inputs!$C$27:$E$27,1,C9) -> 0.03 | J9: =H9*Inputs!$B$18*I9/12*E9 -> 43461.909 | K9: =G9+J9 -> 710095.24 | L9: =IF(A9=1,Inputs!$C$29,0) -> 0 | M9: =IF(A9>=Inputs!$B$9,INDEX(Inputs!$C$30:$E$30,1,C9),0) -> 600000 | N9: =L9+M9 -> 600000 | O9: =K9-N9 -> 110095.24 | P9: =R8 -> 5979809.5 | Q9: =MAX(O9-P9,0) -> 0 | R9: =MAX(P9-O9,0) -> 5869714.3 | S9: =Q9*Inputs!$B$11 -> 0 | T9: =O9-S9 -> 110095.24 | U9: =U8+T9 -> -5869714.3 | V9: =1/(1+Inputs!$B$10)^(A9/12) -> 0.93250481 | W9: =T9*V9 -> 102664.34 | X9: =X8+W9 -> -5788131.2 | Y9: =IF(U9>=0,A9,"") | Z9: =IF(X9>=0,A9,"")
A10: 7 | B10: =EDATE(Inputs!$B$8,A10-1) -> 46357 | C10: =ROUNDUP(A10/12,0) -> 1 | D10: =MOD(A10-1,12)+1 -> 7 | E10: =IF(A10<Inputs!$B$9,0,MIN(1,(A10-Inputs!$B$9+1)/Inputs!$C$32)) -> 0.66666667 | F10: =Inputs!$B$14*Inputs!$B$13*Inputs!$C$23 -> 210 | G10: =F10*Inputs!$B$12*E10 -> 799960 | H10: =INDEX(Inputs!$C$26:$E$26,1,C10) -> 3.1292574e+09 | I10: =INDEX(Inputs!$C$27:$E$27,1,C10) -> 0.03 | J10: =H10*Inputs!$B$18*I10/12*E10 -> 52154.291 | K10: =G10+J10 -> 852114.29 | L10: =IF(A10=1,Inputs!$C$29,0) -> 0 | M10: =IF(A10>=Inputs!$B$9,INDEX(Inputs!$C$30:$E$30,1,C10),0) -> 600000 | N10: =L10+M10 -> 600000 | O10: =K10-N10 -> 252114.29 | P10: =R9 -> 5869714.3 | Q10: =MAX(O10-P10,0) -> 0 | R10: =MAX(P10-O10,0) -> 5617600 | S10: =Q10*Inputs!$B$11 -> 0 | T10: =O10-S10 -> 252114.29 | U10: =U9+T10 -> -5617600 | V10: =1/(1+Inputs!$B$10)^(A10/12) -> 0.92170709 | W10: =T10*V10 -> 232375.53 | X10: =X9+W10 -> -5555755.7 | Y10: =IF(U10>=0,A10,"") | Z10: =IF(X10>=0,A10,"")
A11: 8 | B11: =EDATE(Inputs!$B$8,A11-1) -> 46388 | C11: =ROUNDUP(A11/12,0) -> 1 | D11: =MOD(A11-1,12)+1 -> 8 | E11: =IF(A11<Inputs!$B$9,0,MIN(1,(A11-Inputs!$B$9+1)/Inputs!$C$32)) -> 0.77777778 | F11: =Inputs!$B$14*Inputs!$B$13*Inputs!$C$23 -> 210 | G11: =F11*Inputs!$B$12*E11 -> 933286.67 | H11: =INDEX(Inputs!$C$26:$E$26,1,C11) -> 3.1292574e+09 | I11: =INDEX(Inputs!$C$27:$E$27,1,C11) -> 0.03 | J11: =H11*Inputs!$B$18*I11/12*E11 -> 60846.672 | K11: =G11+J11 -> 994133.34 | L11: =IF(A11=1,Inputs!$C$29,0) -> 0 | M11: =IF(A11>=Inputs!$B$9,INDEX(Inputs!$C$30:$E$30,1,C11),0) -> 600000 | N11: =L11+M11 -> 600000 | O11: =K11-N11 -> 394133.34 | P11: =R10 -> 5617600 | Q11: =MAX(O11-P11,0) -> 0 | R11: =MAX(P11-O11,0) -> 5223466.6 | S11: =Q11*Inputs!$B$11 -> 0 | T11: =O11-S11 -> 394133.34 | U11: =U10+T11 -> -5223466.6 | V11: =1/(1+Inputs!$B$10)^(A11/12) -> 0.91103439 | W11: =T11*V11 -> 359069.03 | X11: =X10+W11 -> -5196686.7 | Y11: =IF(U11>=0,A11,"") | Z11: =IF(X11>=0,A11,"")
A12: 9 | B12: =EDATE(Inputs!$B$8,A12-1) -> 46419 | C12: =ROUNDUP(A12/12,0) -> 1 | D12: =MOD(A12-1,12)+1 -> 9 | E12: =IF(A12<Inputs!$B$9,0,MIN(1,(A12-Inputs!$B$9+1)/Inputs!$C$32)) -> 0.88888889 | F12: =Inputs!$B$14*Inputs!$B$13*Inputs!$C$23 -> 210 | G12: =F12*Inputs!$B$12*E12 -> 1066613.3 | H12: =INDEX(Inputs!$C$26:$E$26,1,C12) -> 3.1292574e+09 | I12: =INDEX(Inputs!$C$27:$E$27,1,C12) -> 0.03 | J12: =H12*Inputs!$B$18*I12/12*E12 -> 69539.054 | K12: =G12+J12 -> 1136152.4 | L12: =IF(A12=1,Inputs!$C$29,0) -> 0 | M12: =IF(A12>=Inputs!$B$9,INDEX(Inputs!$C$30:$E$30,1,C12),0) -> 600000 | N12: =L12+M12 -> 600000 | O12: =K12-N12 -> 536152.39 | P12: =R11 -> 5223466.6 | Q12: =MAX(O12-P12,0) -> 0 | R12: =MAX(P12-O12,0) -> 4687314.3 | S12: =Q12*Inputs!$B$11 -> 0 | T12: =O12-S12 -> 536152.39 | U12: =U11+T12 -> -4687314.3 | V12: =1/(1+Inputs!$B$10)^(A12/12) -> 0.90048528 | W12: =T12*V12 -> 482797.33 | X12: =X11+W12 -> -4713889.3 | Y12: =IF(U12>=0,A12,"") | Z12: =IF(X12>=0,A12,"")
A13: 10 | B13: =EDATE(Inputs!$B$8,A13-1) -> 46447 | C13: =ROUNDUP(A13/12,0) -> 1 | D13: =MOD(A13-1,12)+1 -> 10 | E13: =IF(A13<Inputs!$B$9,0,MIN(1,(A13-Inputs!$B$9+1)/Inputs!$C$32)) -> 1 | F13: =Inputs!$B$14*Inputs!$B$13*Inputs!$C$23 -> 210 | G13: =F13*Inputs!$B$12*E13 -> 1199940 | H13: =INDEX(Inputs!$C$26:$E$26,1,C13) -> 3.1292574e+09 | I13: =INDEX(Inputs!$C$27:$E$27,1,C13) -> 0.03 | J13: =H13*Inputs!$B$18*I13/12*E13 -> 78231.436 | K13: =G13+J13 -> 1278171.4 | L13: =IF(A13=1,Inputs!$C$29,0) -> 0 | M13: =IF(A13>=Inputs!$B$9,INDEX(Inputs!$C$30:$E$30,1,C13),0) -> 600000 | N13: =L13+M13 -> 600000 | O13: =K13-N13 -> 678171.44 | P13: =R12 -> 4687314.3 | Q13: =MAX(O13-P13,0) -> 0 | R13: =MAX(P13-O13,0) -> 4009142.8 | S13: =Q13*Inputs!$B$11 -> 0 | T13: =O13-S13 -> 678171.44 | U13: =U12+T13 -> -4009142.8 | V13: =1/(1+Inputs!$B$10)^(A13/12) -> 0.89005832 | W13: =T13*V13 -> 603612.13 | X13: =X12+W13 -> -4110277.2 | Y13: =IF(U13>=0,A13,"") | Z13: =IF(X13>=0,A13,"")
A14: 11 | B14: =EDATE(Inputs!$B$8,A14-1) -> 46478 | C14: =ROUNDUP(A14/12,0) -> 1 | D14: =MOD(A14-1,12)+1 -> 11 | E14: =IF(A14<Inputs!$B$9,0,MIN(1,(A14-Inputs!$B$9+1)/Inputs!$C$32)) -> 1 | F14: =Inputs!$B$14*Inputs!$B$13*Inputs!$C$23 -> 210 | G14: =F14*Inputs!$B$12*E14 -> 1199940 | H14: =INDEX(Inputs!$C$26:$E$26,1,C14) -> 3.1292574e+09 | I14: =INDEX(Inputs!$C$27:$E$27,1,C14) -> 0.03 | J14: =H14*Inputs!$B$18*I14/12*E14 -> 78231.436 | K14: =G14+J14 -> 1278171.4 | L14: =IF(A14=1,Inputs!$C$29,0) -> 0 | M14: =IF(A14>=Inputs!$B$9,INDEX(Inputs!$C$30:$E$30,1,C14),0) -> 600000 | N14: =L14+M14 -> 600000 | O14: =K14-N14 -> 678171.44 | P14: =R13 -> 4009142.8 | Q14: =MAX(O14-P14,0) -> 0 | R14: =MAX(P14-O14,0) -> 3330971.4 | S14: =Q14*Inputs!$B$11 -> 0 | T14: =O14-S14 -> 678171.44 | U14: =U13+T14 -> -3330971.4 | V14: =1/(1+Inputs!$B$10)^(A14/12) -> 0.8797521 | W14: =T14*V14 -> 596622.75 | X14: =X13+W14 -> -3513654.5 | Y14: =IF(U14>=0,A14,"") | Z14: =IF(X14>=0,A14,"")
A15: 12 | B15: =EDATE(Inputs!$B$8,A15-1) -> 46508 | C15: =ROUNDUP(A15/12,0) -> 1 | D15: =MOD(A15-1,12)+1 -> 12 | E15: =IF(A15<Inputs!$B$9,0,MIN(1,(A15-Inputs!$B$9+1)/Inputs!$C$32)) -> 1 | F15: =Inputs!$B$14*Inputs!$B$13*Inputs!$C$23 -> 210 | G15: =F15*Inputs!$B$12*E15 -> 1199940 | H15: =INDEX(Inputs!$C$26:$E$26,1,C15) -> 3.1292574e+09 | I15: =INDEX(Inputs!$C$27:$E$27,1,C15) -> 0.03 | J15: =H15*Inputs!$B$18*I15/12*E15 -> 78231.436 | K15: =G15+J15 -> 1278171.4 | L15: =IF(A15=1,Inputs!$C$29,0) -> 0 | M15: =IF(A15>=Inputs!$B$9,INDEX(Inputs!$C$30:$E$30,1,C15),0) -> 600000 | N15: =L15+M15 -> 600000 | O15: =K15-N15 -> 678171.44 | P15: =R14 -> 3330971.4 | Q15: =MAX(O15-P15,0) -> 0 | R15: =MAX(P15-O15,0) -> 2652799.9 | S15: =Q15*Inputs!$B$11 -> 0 | T15: =O15-S15 -> 678171.44 | U15: =U14+T15 -> -2652799.9 | V15: =1/(1+Inputs!$B$10)^(A15/12) -> 0.86956522 | W15: =T15*V15 -> 589714.29 | X15: =X14+W15 -> -2923940.2 | Y15: =IF(U15>=0,A15,"") | Z15: =IF(X15>=0,A15,"")
A16: 13 | B16: =EDATE(Inputs!$B$8,A16-1) -> 46539 | C16: =ROUNDUP(A16/12,0) -> 2 | D16: =MOD(A16-1,12)+1 -> 1 | E16: =IF(A16<Inputs!$B$9,0,MIN(1,(A16-Inputs!$B$9+1)/Inputs!$C$32)) -> 1 | F16: =Inputs!$B$14*Inputs!$B$13*Inputs!$C$23 -> 210 | G16: =F16*Inputs!$B$12*E16 -> 1199940 | H16: =INDEX(Inputs!$C$26:$E$26,1,C16) -> 4.0680347e+09 | I16: =INDEX(Inputs!$C$27:$E$27,1,C16) -> 0.03 | J16: =H16*Inputs!$B$18*I16/12*E16 -> 101700.87 | K16: =G16+J16 -> 1301640.9 | L16: =IF(A16=1,Inputs!$C$29,0) -> 0 | M16: =IF(A16>=Inputs!$B$9,INDEX(Inputs!$C$30:$E$30,1,C16),0) -> 640000 | N16: =L16+M16 -> 640000 | O16: =K16-N16 -> 661640.87 | P16: =R15 -> 2652799.9 | Q16: =MAX(O16-P16,0) -> 0 | R16: =MAX(P16-O16,0) -> 1991159.1 | S16: =Q16*Inputs!$B$11 -> 0 | T16: =O16-S16 -> 661640.87 | U16: =U15+T16 -> -1991159.1 | V16: =1/(1+Inputs!$B$10)^(A16/12) -> 0.85949629 | W16: =T16*V16 -> 568677.87 | X16: =X15+W16 -> -2355262.3 | Y16: =IF(U16>=0,A16,"") | Z16: =IF(X16>=0,A16,"")
... A39: 36 | B39: =EDATE(Inputs!$B$8,A39-1) -> 47239 | C39: =ROUNDUP(A39/12,0) -> 3 | D39: =MOD(A39-1,12)+1 -> 12 | E39: =IF(A39<Inputs!$B$9,0,MIN(1,(A39-Inputs!$B$9+1)/Inputs!$C$32)) -> 1 | F39: =Inputs!$B$14*Inputs!$B$13*Inputs!$C$23 -> 210 | G39: =F39*Inputs!$B$12*E39 -> 1199940 | H39: =INDEX(Inputs!$C$26:$E$26,1,C39) -> 5.2884451e+09 | I39: =INDEX(Inputs!$C$27:$E$27,1,C39) -> 0.03 | J39: =H39*Inputs!$B$18*I39/12*E39 -> 132211.13 | K39: =G39+J39 -> 1332151.1 | L39: =IF(A39=1,Inputs!$C$29,0) -> 0 | M39: =IF(A39>=Inputs!$B$9,INDEX(Inputs!$C$30:$E$30,1,C39),0) -> 690000 | N39: =L39+M39 -> 690000 | O39: =K39-N39 -> 642151.13 | P39: =R38 -> 0 | Q39: =MAX(O39-P39,0) -> 642151.13 | R39: =MAX(P39-O39,0) -> 0 | S39: =Q39*Inputs!$B$11 -> 128430.23 | T39: =O39-S39 -> 513720.9 | U39: =U38+T39 -> 10394163 | V39: =1/(1+Inputs!$B$10)^(A39/12) -> 0.65751623 | W39: =T39*V39 -> 337779.83 | X39: =X38+W39 -> 6973883.5 | Y39: =IF(U39>=0,A39,"") -> 36 | Z39: =IF(X39>=0,A39,"") -> 36
A41: ИТОГИ ПО ГОДАМ И МЕТРИКИ ОКУПАЕМОСТИ
A42: Показатель | B42: Год 1 | C42: Год 2 | D42: Год 3 | E42: Итого / Значение
A43: Выгоды (экономия), ₸ | B43: =SUM(K4:K15) -> 8947200.1 | C43: =SUM(K16:K27) -> 15619690 | D43: =SUM(K28:K39) -> 15985814 | E43: =SUM(K4:K39) -> 40552704
A44: Затраты (разработка + опер.), ₸ | B44: =SUM(N4:N15) -> 11600000 | C44: =SUM(N16:N27) -> 7680000 | D44: =SUM(N28:N39) -> 8280000 | E44: =SUM(N4:N39) -> 27560000
A45: Прибыль до налога, ₸ | B45: =SUM(O4:O15) -> -2652799.9 | C45: =SUM(O16:O27) -> 7939690.4 | D45: =SUM(O28:O39) -> 7705813.5 | E45: =SUM(O4:O39) -> 12992704
A46: Налог (КПН), ₸ | B46: =SUM(S4:S15) -> 0 | C46: =SUM(S16:S27) -> 1057378.1 | D46: =SUM(S28:S39) -> 1541162.7 | E46: =SUM(S4:S39) -> 2598540.8
A47: Чистая выгода (после налога), ₸ | B47: =SUM(T4:T15) -> -2652799.9 | C47: =SUM(T16:T27) -> 6882312.3 | D47: =SUM(T28:T39) -> 6164650.8 | E47: =SUM(T4:T39) -> 10394163
A48: Накопл. чистая выгода, ₸ | B48: =U15 -> -2652799.9 | C48: =U27 -> 4229512.4 | D48: =U39 -> 10394163 | E48: =U39 -> 10394163
A50: NPV при ставке диск., ₸ | E50: =SUM(W4:W39) -> 6973883.5
A51: IRR (годовая) | E51: =IFERROR((1+IRR(T4:T39))^12-1,"n/a") -> 0.96546688
A52: Простая окупаемость, мес | E52: =IFERROR(SMALL(Y4:Y39,1),">36") -> 17
A53: Дисконт. окупаемость, мес | E53: =IFERROR(SMALL(Z4:Z39,1),">36") -> 18
A54: ROI за 3 года (чист.выгода/затраты) | E54: =E47/E44 -> 0.3771467
A55: PV выгод, ₸ | E55: =SUMPRODUCT(K4:K39,V4:V39) -> 31923120
A56: PV затрат, ₸ | E56: =SUMPRODUCT(N4:N39,V4:V39) -> 23034936
A57: Выгода / затраты (BCR) | E57: =E55/E56 -> 1.3858567

Sheet Calc_Base
A1: Расчёт · РЕАЛИСТИЧНЫЙ сценарий
A2: Помесячный расчёт (36 мес). Денежные суммы — в ₸ (точные). Читает только колонки своего сценария с листа Inputs.
A3: № мес | B3: Дата | C3: Год | D3: Мес в году | E3: Адаптация | F3: Сэкон. часов/мес | G3: Экономия труда | H3: База компенсаций | I3: Доля невыявл. ошибок | J3: Экономия от риска | K3: Итого выгоды | L3: Разработка | M3: Опер. расходы | N3: Итого затраты | O3: Прибыль до налога | P3: Перенос убытка (вх.) | Q3: Налогооблагаемая | R3: Перенос убытка (исх.) | S3: Налог КПН | T3: Чистая выгода | U3: Накопл. чистая выгода | V3: Дисконт-фактор | W3: Дисконт. выгода | X3: Накопл. дисконт. выгода | Y3: Окупаемость (флаг) | Z3: Дисконт. окуп. (флаг)
A4: 1 | B4: =EDATE(Inputs!$B$8,A4-1) -> 46174 | C4: =ROUNDUP(A4/12,0) -> 1 | D4: =MOD(A4-1,12)+1 -> 1 | E4: =IF(A4<Inputs!$B$9,0,MIN(1,(A4-Inputs!$B$9+1)/Inputs!$F$32)) -> 0 | F4: =Inputs!$B$14*Inputs!$B$13*Inputs!$F$23 -> 245 | G4: =F4*Inputs!$B$12*E4 -> 0 | H4: =INDEX(Inputs!$F$26:$H$26,1,C4) -> 3.4903256e+09 | I4: =INDEX(Inputs!$F$27:$H$27,1,C4) -> 0.05 | J4: =H4*Inputs!$B$18*I4/12*E4 -> 0 | K4: =G4+J4 -> 0 | L4: =IF(A4=1,Inputs!$F$29,0) -> 5000000 | M4: =IF(A4>=Inputs!$B$9,INDEX(Inputs!$F$30:$H$30,1,C4),0) -> 0 | N4: =L4+M4 -> 5000000 | O4: =K4-N4 -> -5000000 | P4: =0 -> 0 | Q4: =MAX(O4-P4,0) -> 0 | R4: =MAX(P4-O4,0) -> 5000000 | S4: =Q4*Inputs!$B$11 -> 0 | T4: =O4-S4 -> -5000000 | U4: =T4 -> -5000000 | V4: =1/(1+Inputs!$B$10)^(A4/12) -> 0.98842073 | W4: =T4*V4 -> -4942103.7 | X4: =W4 -> -4942103.7 | Y4: =IF(U4>=0,A4,"") | Z4: =IF(X4>=0,A4,"")
A5: 2 | B5: =EDATE(Inputs!$B$8,A5-1) -> 46204 | C5: =ROUNDUP(A5/12,0) -> 1 | D5: =MOD(A5-1,12)+1 -> 2 | E5: =IF(A5<Inputs!$B$9,0,MIN(1,(A5-Inputs!$B$9+1)/Inputs!$F$32)) -> 0.16666667 | F5: =Inputs!$B$14*Inputs!$B$13*Inputs!$F$23 -> 245 | G5: =F5*Inputs!$B$12*E5 -> 233321.67 | H5: =INDEX(Inputs!$F$26:$H$26,1,C5) -> 3.4903256e+09 | I5: =INDEX(Inputs!$F$27:$H$27,1,C5) -> 0.05 | J5: =H5*Inputs!$B$18*I5/12*E5 -> 24238.372 | K5: =G5+J5 -> 257560.04 | L5: =IF(A5=1,Inputs!$F$29,0) -> 0 | M5: =IF(A5>=Inputs!$B$9,INDEX(Inputs!$F$30:$H$30,1,C5),0) -> 500000 | N5: =L5+M5 -> 500000 | O5: =K5-N5 -> -242439.96 | P5: =R4 -> 5000000 | Q5: =MAX(O5-P5,0) -> 0 | R5: =MAX(P5-O5,0) -> 5242440 | S5: =Q5*Inputs!$B$11 -> 0 | T5: =O5-S5 -> -242439.96 | U5: =U4+T5 -> -5242440 | V5: =1/(1+Inputs!$B$10)^(A5/12) -> 0.97697555 | W5: =T5*V5 -> -236857.91 | X5: =X4+W5 -> -5178961.6 | Y5: =IF(U5>=0,A5,"") | Z5: =IF(X5>=0,A5,"")
A6: 3 | B6: =EDATE(Inputs!$B$8,A6-1) -> 46235 | C6: =ROUNDUP(A6/12,0) -> 1 | D6: =MOD(A6-1,12)+1 -> 3 | E6: =IF(A6<Inputs!$B$9,0,MIN(1,(A6-Inputs!$B$9+1)/Inputs!$F$32)) -> 0.33333333 | F6: =Inputs!$B$14*Inputs!$B$13*Inputs!$F$23 -> 245 | G6: =F6*Inputs!$B$12*E6 -> 466643.33 | H6: =INDEX(Inputs!$F$26:$H$26,1,C6) -> 3.4903256e+09 | I6: =INDEX(Inputs!$F$27:$H$27,1,C6) -> 0.05 | J6: =H6*Inputs!$B$18*I6/12*E6 -> 48476.744 | K6: =G6+J6 -> 515120.08 | L6: =IF(A6=1,Inputs!$F$29,0) -> 0 | M6: =IF(A6>=Inputs!$B$9,INDEX(Inputs!$F$30:$H$30,1,C6),0) -> 500000 | N6: =L6+M6 -> 500000 | O6: =K6-N6 -> 15120.078 | P6: =R5 -> 5242440 | Q6: =MAX(O6-P6,0) -> 0 | R6: =MAX(P6-O6,0) -> 5227319.9 | S6: =Q6*Inputs!$B$11 -> 0 | T6: =O6-S6 -> 15120.078 | U6: =U5+T6 -> -5227319.9 | V6: =1/(1+Inputs!$B$10)^(A6/12) -> 0.96566289 | W6: =T6*V6 -> 14600.898 | X6: =X5+W6 -> -5164360.7 | Y6: =IF(U6>=0,A6,"") | Z6: =IF(X6>=0,A6,"")
A7: 4 | B7: =EDATE(Inputs!$B$8,A7-1) -> 46266 | C7: =ROUNDUP(A7/12,0) -> 1 | D7: =MOD(A7-1,12)+1 -> 4 | E7: =IF(A7<Inputs!$B$9,0,MIN(1,(A7-Inputs!$B$9+1)/Inputs!$F$32)) -> 0.5 | F7: =Inputs!$B$14*Inputs!$B$13*Inputs!$F$23 -> 245 | G7: =F7*Inputs!$B$12*E7 -> 699965 | H7: =INDEX(Inputs!$F$26:$H$26,1,C7) -> 3.4903256e+09 | I7: =INDEX(Inputs!$F$27:$H$27,1,C7) -> 0.05 | J7: =H7*Inputs!$B$18*I7/12*E7 -> 72715.117 | K7: =G7+J7 -> 772680.12 | L7: =IF(A7=1,Inputs!$F$29,0) -> 0 | M7: =IF(A7>=Inputs!$B$9,INDEX(Inputs!$F$30:$H$30,1,C7),0) -> 500000 | N7: =L7+M7 -> 500000 | O7: =K7-N7 -> 272680.12 | P7: =R6 -> 5227319.9 | Q7: =MAX(O7-P7,0) -> 0 | R7: =MAX(P7-O7,0) -> 4954639.8 | S7: =Q7*Inputs!$B$11 -> 0 | T7: =O7-S7 -> 272680.12 | U7: =U6+T7 -> -4954639.8 | V7: =1/(1+Inputs!$B$10)^(A7/12) -> 0.95448122 | W7: =T7*V7 -> 260268.05 | X7: =X6+W7 -> -4904092.6 | Y7: =IF(U7>=0,A7,"") | Z7: =IF(X7>=0,A7,"")
A8: 5 | B8: =EDATE(Inputs!$B$8,A8-1) -> 46296 | C8: =ROUNDUP(A8/12,0) -> 1 | D8: =MOD(A8-1,12)+1 -> 5 | E8: =IF(A8<Inputs!$B$9,0,MIN(1,(A8-Inputs!$B$9+1)/Inputs!$F$32)) -> 0.66666667 | F8: =Inputs!$B$14*Inputs!$B$13*Inputs!$F$23 -> 245 | G8: =F8*Inputs!$B$12*E8 -> 933286.67 | H8: =INDEX(Inputs!$F$26:$H$26,1,C8) -> 3.4903256e+09 | I8: =INDEX(Inputs!$F$27:$H$27,1,C8) -> 0.05 | J8: =H8*Inputs!$B$18*I8/12*E8 -> 96953.489 | K8: =G8+J8 -> 1030240.2 | L8: =IF(A8=1,Inputs!$F$29,0) -> 0 | M8: =IF(A8>=Inputs!$B$9,INDEX(Inputs!$F$30:$H$30,1,C8),0) -> 500000 | N8: =L8+M8 -> 500000 | O8: =K8-N8 -> 530240.16 | P8: =R7 -> 4954639.8 | Q8: =MAX(O8-P8,0) -> 0 | R8: =MAX(P8-O8,0) -> 4424399.6 | S8: =Q8*Inputs!$B$11 -> 0 | T8: =O8-S8 -> 530240.16 | U8: =U7+T8 -> -4424399.6 | V8: =1/(1+Inputs!$B$10)^(A8/12) -> 0.94342902 | W8: =T8*V8 -> 500243.95 | X8: =X7+W8 -> -4403848.7 | Y8: =IF(U8>=0,A8,"") | Z8: =IF(X8>=0,A8,"")
A9: 6 | B9: =EDATE(Inputs!$B$8,A9-1) -> 46327 | C9: =ROUNDUP(A9/12,0) -> 1 | D9: =MOD(A9-1,12)+1 -> 6 | E9: =IF(A9<Inputs!$B$9,0,MIN(1,(A9-Inputs!$B$9+1)/Inputs!$F$32)) -> 0.83333333 | F9: =Inputs!$B$14*Inputs!$B$13*Inputs!$F$23 -> 245 | G9: =F9*Inputs!$B$12*E9 -> 1166608.3 | H9: =INDEX(Inputs!$F$26:$H$26,1,C9) -> 3.4903256e+09 | I9: =INDEX(Inputs!$F$27:$H$27,1,C9) -> 0.05 | J9: =H9*Inputs!$B$18*I9/12*E9 -> 121191.86 | K9: =G9+J9 -> 1287800.2 | L9: =IF(A9=1,Inputs!$F$29,0) -> 0 | M9: =IF(A9>=Inputs!$B$9,INDEX(Inputs!$F$30:$H$30,1,C9),0) -> 500000 | N9: =L9+M9 -> 500000 | O9: =K9-N9 -> 787800.19 | P9: =R8 -> 4424399.6 | Q9: =MAX(O9-P9,0) -> 0 | R9: =MAX(P9-O9,0) -> 3636599.4 | S9: =Q9*Inputs!$B$11 -> 0 | T9: =O9-S9 -> 787800.19 | U9: =U8+T9 -> -3636599.4 | V9: =1/(1+Inputs!$B$10)^(A9/12) -> 0.93250481 | W9: =T9*V9 -> 734627.47 | X9: =X8+W9 -> -3669221.2 | Y9: =IF(U9>=0,A9,"") | Z9: =IF(X9>=0,A9,"")
A10: 7 | B10: =EDATE(Inputs!$B$8,A10-1) -> 46357 | C10: =ROUNDUP(A10/12,0) -> 1 | D10: =MOD(A10-1,12)+1 -> 7 | E10: =IF(A10<Inputs!$B$9,0,MIN(1,(A10-Inputs!$B$9+1)/Inputs!$F$32)) -> 1 | F10: =Inputs!$B$14*Inputs!$B$13*Inputs!$F$23 -> 245 | G10: =F10*Inputs!$B$12*E10 -> 1399930 | H10: =INDEX(Inputs!$F$26:$H$26,1,C10) -> 3.4903256e+09 | I10: =INDEX(Inputs!$F$27:$H$27,1,C10) -> 0.05 | J10: =H10*Inputs!$B$18*I10/12*E10 -> 145430.23 | K10: =G10+J10 -> 1545360.2 | L10: =IF(A10=1,Inputs!$F$29,0) -> 0 | M10: =IF(A10>=Inputs!$B$9,INDEX(Inputs!$F$30:$H$30,1,C10),0) -> 500000 | N10: =L10+M10 -> 500000 | O10: =K10-N10 -> 1045360.2 | P10: =R9 -> 3636599.4 | Q10: =MAX(O10-P10,0) -> 0 | R10: =MAX(P10-O10,0) -> 2591239.2 | S10: =Q10*Inputs!$B$11 -> 0 | T10: =O10-S10 -> 1045360.2 | U10: =U9+T10 -> -2591239.2 | V10: =1/(1+Inputs!$B$10)^(A10/12) -> 0.92170709 | W10: =T10*V10 -> 963515.93 | X10: =X9+W10 -> -2705705.3 | Y10: =IF(U10>=0,A10,"") | Z10: =IF(X10>=0,A10,"")
A11: 8 | B11: =EDATE(Inputs!$B$8,A11-1) -> 46388 | C11: =ROUNDUP(A11/12,0) -> 1 | D11: =MOD(A11-1,12)+1 -> 8 | E11: =IF(A11<Inputs!$B$9,0,MIN(1,(A11-Inputs!$B$9+1)/Inputs!$F$32)) -> 1 | F11: =Inputs!$B$14*Inputs!$B$13*Inputs!$F$23 -> 245 | G11: =F11*Inputs!$B$12*E11 -> 1399930 | H11: =INDEX(Inputs!$F$26:$H$26,1,C11) -> 3.4903256e+09 | I11: =INDEX(Inputs!$F$27:$H$27,1,C11) -> 0.05 | J11: =H11*Inputs!$B$18*I11/12*E11 -> 145430.23 | K11: =G11+J11 -> 1545360.2 | L11: =IF(A11=1,Inputs!$F$29,0) -> 0 | M11: =IF(A11>=Inputs!$B$9,INDEX(Inputs!$F$30:$H$30,1,C11),0) -> 500000 | N11: =L11+M11 -> 500000 | O11: =K11-N11 -> 1045360.2 | P11: =R10 -> 2591239.2 | Q11: =MAX(O11-P11,0) -> 0 | R11: =MAX(P11-O11,0) -> 1545878.9 | S11: =Q11*Inputs!$B$11 -> 0 | T11: =O11-S11 -> 1045360.2 | U11: =U10+T11 -> -1545878.9 | V11: =1/(1+Inputs!$B$10)^(A11/12) -> 0.91103439 | W11: =T11*V11 -> 952359.13 | X11: =X10+W11 -> -1753346.1 | Y11: =IF(U11>=0,A11,"") | Z11: =IF(X11>=0,A11,"")
A12: 9 | B12: =EDATE(Inputs!$B$8,A12-1) -> 46419 | C12: =ROUNDUP(A12/12,0) -> 1 | D12: =MOD(A12-1,12)+1 -> 9 | E12: =IF(A12<Inputs!$B$9,0,MIN(1,(A12-Inputs!$B$9+1)/Inputs!$F$32)) -> 1 | F12: =Inputs!$B$14*Inputs!$B$13*Inputs!$F$23 -> 245 | G12: =F12*Inputs!$B$12*E12 -> 1399930 | H12: =INDEX(Inputs!$F$26:$H$26,1,C12) -> 3.4903256e+09 | I12: =INDEX(Inputs!$F$27:$H$27,1,C12) -> 0.05 | J12: =H12*Inputs!$B$18*I12/12*E12 -> 145430.23 | K12: =G12+J12 -> 1545360.2 | L12: =IF(A12=1,Inputs!$F$29,0) -> 0 | M12: =IF(A12>=Inputs!$B$9,INDEX(Inputs!$F$30:$H$30,1,C12),0) -> 500000 | N12: =L12+M12 -> 500000 | O12: =K12-N12 -> 1045360.2 | P12: =R11 -> 1545878.9 | Q12: =MAX(O12-P12,0) -> 0 | R12: =MAX(P12-O12,0) -> 500518.72 | S12: =Q12*Inputs!$B$11 -> 0 | T12: =O12-S12 -> 1045360.2 | U12: =U11+T12 -> -500518.72 | V12: =1/(1+Inputs!$B$10)^(A12/12) -> 0.90048528 | W12: =T12*V12 -> 941331.51 | X12: =X11+W12 -> -812014.64 | Y12: =IF(U12>=0,A12,"") | Z12: =IF(X12>=0,A12,"")
A13: 10 | B13: =EDATE(Inputs!$B$8,A13-1) -> 46447 | C13: =ROUNDUP(A13/12,0) -> 1 | D13: =MOD(A13-1,12)+1 -> 10 | E13: =IF(A13<Inputs!$B$9,0,MIN(1,(A13-Inputs!$B$9+1)/Inputs!$F$32)) -> 1 | F13: =Inputs!$B$14*Inputs!$B$13*Inputs!$F$23 -> 245 | G13: =F13*Inputs!$B$12*E13 -> 1399930 | H13: =INDEX(Inputs!$F$26:$H$26,1,C13) -> 3.4903256e+09 | I13: =INDEX(Inputs!$F$27:$H$27,1,C13) -> 0.05 | J13: =H13*Inputs!$B$18*I13/12*E13 -> 145430.23 | K13: =G13+J13 -> 1545360.2 | L13: =IF(A13=1,Inputs!$F$29,0) -> 0 | M13: =IF(A13>=Inputs!$B$9,INDEX(Inputs!$F$30:$H$30,1,C13),0) -> 500000 | N13: =L13+M13 -> 500000 | O13: =K13-N13 -> 1045360.2 | P13: =R12 -> 500518.72 | Q13: =MAX(O13-P13,0) -> 544841.52 | R13: =MAX(P13-O13,0) -> 0 | S13: =Q13*Inputs!$B$11 -> 108968.3 | T13: =O13-S13 -> 936391.93 | U13: =U12+T13 -> 435873.21 | V13: =1/(1+Inputs!$B$10)^(A13/12) -> 0.89005832 | W13: =T13*V13 -> 833443.43 | X13: =X12+W13 -> 21428.791 | Y13: =IF(U13>=0,A13,"") -> 10 | Z13: =IF(X13>=0,A13,"") -> 10
A14: 11 | B14: =EDATE(Inputs!$B$8,A14-1) -> 46478 | C14: =ROUNDUP(A14/12,0) -> 1 | D14: =MOD(A14-1,12)+1 -> 11 | E14: =IF(A14<Inputs!$B$9,0,MIN(1,(A14-Inputs!$B$9+1)/Inputs!$F$32)) -> 1 | F14: =Inputs!$B$14*Inputs!$B$13*Inputs!$F$23 -> 245 | G14: =F14*Inputs!$B$12*E14 -> 1399930 | H14: =INDEX(Inputs!$F$26:$H$26,1,C14) -> 3.4903256e+09 | I14: =INDEX(Inputs!$F$27:$H$27,1,C14) -> 0.05 | J14: =H14*Inputs!$B$18*I14/12*E14 -> 145430.23 | K14: =G14+J14 -> 1545360.2 | L14: =IF(A14=1,Inputs!$F$29,0) -> 0 | M14: =IF(A14>=Inputs!$B$9,INDEX(Inputs!$F$30:$H$30,1,C14),0) -> 500000 | N14: =L14+M14 -> 500000 | O14: =K14-N14 -> 1045360.2 | P14: =R13 -> 0 | Q14: =MAX(O14-P14,0) -> 1045360.2 | R14: =MAX(P14-O14,0) -> 0 | S14: =Q14*Inputs!$B$11 -> 209072.05 | T14: =O14-S14 -> 836288.19 | U14: =U13+T14 -> 1272161.4 | V14: =1/(1+Inputs!$B$10)^(A14/12) -> 0.8797521 | W14: =T14*V14 -> 735726.29 | X14: =X13+W14 -> 757155.08 | Y14: =IF(U14>=0,A14,"") -> 11 | Z14: =IF(X14>=0,A14,"") -> 11
A15: 12 | B15: =EDATE(Inputs!$B$8,A15-1) -> 46508 | C15: =ROUNDUP(A15/12,0) -> 1 | D15: =MOD(A15-1,12)+1 -> 12 | E15: =IF(A15<Inputs!$B$9,0,MIN(1,(A15-Inputs!$B$9+1)/Inputs!$F$32)) -> 1 | F15: =Inputs!$B$14*Inputs!$B$13*Inputs!$F$23 -> 245 | G15: =F15*Inputs!$B$12*E15 -> 1399930 | H15: =INDEX(Inputs!$F$26:$H$26,1,C15) -> 3.4903256e+09 | I15: =INDEX(Inputs!$F$27:$H$27,1,C15) -> 0.05 | J15: =H15*Inputs!$B$18*I15/12*E15 -> 145430.23 | K15: =G15+J15 -> 1545360.2 | L15: =IF(A15=1,Inputs!$F$29,0) -> 0 | M15: =IF(A15>=Inputs!$B$9,INDEX(Inputs!$F$30:$H$30,1,C15),0) -> 500000 | N15: =L15+M15 -> 500000 | O15: =K15-N15 -> 1045360.2 | P15: =R14 -> 0 | Q15: =MAX(O15-P15,0) -> 1045360.2 | R15: =MAX(P15-O15,0) -> 0 | S15: =Q15*Inputs!$B$11 -> 209072.05 | T15: =O15-S15 -> 836288.19 | U15: =U14+T15 -> 2108449.6 | V15: =1/(1+Inputs!$B$10)^(A15/12) -> 0.86956522 | W15: =T15*V15 -> 727207.12 | X15: =X14+W15 -> 1484362.2 | Y15: =IF(U15>=0,A15,"") -> 12 | Z15: =IF(X15>=0,A15,"") -> 12
A16: 13 | B16: =EDATE(Inputs!$B$8,A16-1) -> 46539 | C16: =ROUNDUP(A16/12,0) -> 2 | D16: =MOD(A16-1,12)+1 -> 1 | E16: =IF(A16<Inputs!$B$9,0,MIN(1,(A16-Inputs!$B$9+1)/Inputs!$F$32)) -> 1 | F16: =Inputs!$B$14*Inputs!$B$13*Inputs!$F$23 -> 245 | G16: =F16*Inputs!$B$12*E16 -> 1399930 | H16: =INDEX(Inputs!$F$26:$H$26,1,C16) -> 5.0609721e+09 | I16: =INDEX(Inputs!$F$27:$H$27,1,C16) -> 0.05 | J16: =H16*Inputs!$B$18*I16/12*E16 -> 210873.84 | K16: =G16+J16 -> 1610803.8 | L16: =IF(A16=1,Inputs!$F$29,0) -> 0 | M16: =IF(A16>=Inputs!$B$9,INDEX(Inputs!$F$30:$H$30,1,C16),0) -> 520000 | N16: =L16+M16 -> 520000 | O16: =K16-N16 -> 1090803.8 | P16: =R15 -> 0 | Q16: =MAX(O16-P16,0) -> 1090803.8 | R16: =MAX(P16-O16,0) -> 0 | S16: =Q16*Inputs!$B$11 -> 218160.77 | T16: =O16-S16 -> 872643.07 | U16: =U15+T16 -> 2981092.7 | V16: =1/(1+Inputs!$B$10)^(A16/12) -> 0.85949629 | W16: =T16*V16 -> 750033.48 | X16: =X15+W16 -> 2234395.7 | Y16: =IF(U16>=0,A16,"") -> 13 | Z16: =IF(X16>=0,A16,"") -> 13
... A39: 36 | B39: =EDATE(Inputs!$B$8,A39-1) -> 47239 | C39: =ROUNDUP(A39/12,0) -> 3 | D39: =MOD(A39-1,12)+1 -> 12 | E39: =IF(A39<Inputs!$B$9,0,MIN(1,(A39-Inputs!$B$9+1)/Inputs!$F$32)) -> 1 | F39: =Inputs!$B$14*Inputs!$B$13*Inputs!$F$23 -> 245 | G39: =F39*Inputs!$B$12*E39 -> 1399930 | H39: =INDEX(Inputs!$F$26:$H$26,1,C39) -> 7.3384096e+09 | I39: =INDEX(Inputs!$F$27:$H$27,1,C39) -> 0.05 | J39: =H39*Inputs!$B$18*I39/12*E39 -> 305767.07 | K39: =G39+J39 -> 1705697.1 | L39: =IF(A39=1,Inputs!$F$29,0) -> 0 | M39: =IF(A39>=Inputs!$B$9,INDEX(Inputs!$F$30:$H$30,1,C39),0) -> 550000 | N39: =L39+M39 -> 550000 | O39: =K39-N39 -> 1155697.1 | P39: =R38 -> 0 | Q39: =MAX(O39-P39,0) -> 1155697.1 | R39: =MAX(P39-O39,0) -> 0 | S39: =Q39*Inputs!$B$11 -> 231139.41 | T39: =O39-S39 -> 924557.65 | U39: =U38+T39 -> 23674858 | V39: =1/(1+Inputs!$B$10)^(A39/12) -> 0.65751623 | W39: =T39*V39 -> 607911.66 | X39: =X38+W39 -> 17716938 | Y39: =IF(U39>=0,A39,"") -> 36 | Z39: =IF(X39>=0,A39,"") -> 36
A41: ИТОГИ ПО ГОДАМ И МЕТРИКИ ОКУПАЕМОСТИ
A42: Показатель | B42: Год 1 | C42: Год 2 | D42: Год 3 | E42: Итого / Значение
A43: Выгоды (экономия), ₸ | B43: =SUM(K4:K15) -> 13135562 | C43: =SUM(K16:K27) -> 19329646 | D43: =SUM(K28:K39) -> 20468365 | E43: =SUM(K4:K39) -> 52933573
A44: Затраты (разработка + опер.), ₸ | B44: =SUM(N4:N15) -> 10500000 | C44: =SUM(N16:N27) -> 6240000 | D44: =SUM(N28:N39) -> 6600000 | E44: =SUM(N4:N39) -> 23340000
A45: Прибыль до налога, ₸ | B45: =SUM(O4:O15) -> 2635562 | C45: =SUM(O16:O27) -> 13089646 | D45: =SUM(O28:O39) -> 13868365 | E45: =SUM(O4:O39) -> 29593573
A46: Налог (КПН), ₸ | B46: =SUM(S4:S15) -> 527112.4 | C46: =SUM(S16:S27) -> 2617929.2 | D46: =SUM(S28:S39) -> 2773673 | E46: =SUM(S4:S39) -> 5918714.6
A47: Чистая выгода (после налога), ₸ | B47: =SUM(T4:T15) -> 2108449.6 | C47: =SUM(T16:T27) -> 10471717 | D47: =SUM(T28:T39) -> 11094692 | E47: =SUM(T4:T39) -> 23674858
A48: Накопл. чистая выгода, ₸ | B48: =U15 -> 2108449.6 | C48: =U27 -> 12580166 | D48: =U39 -> 23674858 | E48: =U39 -> 23674858
A50: NPV при ставке диск., ₸ | E50: =SUM(W4:W39) -> 17716938
A51: IRR (годовая) | E51: =IFERROR((1+IRR(T4:T39))^12-1,"n/a") -> 2.9136048
A52: Простая окупаемость, мес | E52: =IFERROR(SMALL(Y4:Y39,1),">36") -> 10
A53: Дисконт. окупаемость, мес | E53: =IFERROR(SMALL(Z4:Z39,1),">36") -> 10
A54: ROI за 3 года (чист.выгода/затраты) | E54: =E47/E44 -> 1.014347
A55: PV выгод, ₸ | E55: =SUMPRODUCT(K4:K39,V4:V39) -> 41917703
A56: PV затрат, ₸ | E56: =SUMPRODUCT(N4:N39,V4:V39) -> 19679899
A57: Выгода / затраты (BCR) | E57: =E55/E56 -> 2.1299755

Sheet Calc_Opt
A1: Расчёт · ОПТИМИСТИЧНЫЙ сценарий
A2: Помесячный расчёт (36 мес). Денежные суммы — в ₸ (точные). Читает только колонки своего сценария с листа Inputs.
A3: № мес | B3: Дата | C3: Год | D3: Мес в году | E3: Адаптация | F3: Сэкон. часов/мес | G3: Экономия труда | H3: База компенсаций | I3: Доля невыявл. ошибок | J3: Экономия от риска | K3: Итого выгоды | L3: Разработка | M3: Опер. расходы | N3: Итого затраты | O3: Прибыль до налога | P3: Перенос убытка (вх.) | Q3: Налогооблагаемая | R3: Перенос убытка (исх.) | S3: Налог КПН | T3: Чистая выгода | U3: Накопл. чистая выгода | V3: Дисконт-фактор | W3: Дисконт. выгода | X3: Накопл. дисконт. выгода | Y3: Окупаемость (флаг) | Z3: Дисконт. окуп. (флаг)
A4: 1 | B4: =EDATE(Inputs!$B$8,A4-1) -> 46174 | C4: =ROUNDUP(A4/12,0) -> 1 | D4: =MOD(A4-1,12)+1 -> 1 | E4: =IF(A4<Inputs!$B$9,0,MIN(1,(A4-Inputs!$B$9+1)/Inputs!$I$32)) -> 0 | F4: =Inputs!$B$14*Inputs!$B$13*Inputs!$I$23 -> 280 | G4: =F4*Inputs!$B$12*E4 -> 0 | H4: =INDEX(Inputs!$I$26:$K$26,1,C4) -> 3.9717498e+09 | I4: =INDEX(Inputs!$I$27:$K$27,1,C4) -> 0.07 | J4: =H4*Inputs!$B$18*I4/12*E4 -> 0 | K4: =G4+J4 -> 0 | L4: =IF(A4=1,Inputs!$I$29,0) -> 5000000 | M4: =IF(A4>=Inputs!$B$9,INDEX(Inputs!$I$30:$K$30,1,C4),0) -> 0 | N4: =L4+M4 -> 5000000 | O4: =K4-N4 -> -5000000 | P4: =0 -> 0 | Q4: =MAX(O4-P4,0) -> 0 | R4: =MAX(P4-O4,0) -> 5000000 | S4: =Q4*Inputs!$B$11 -> 0 | T4: =O4-S4 -> -5000000 | U4: =T4 -> -5000000 | V4: =1/(1+Inputs!$B$10)^(A4/12) -> 0.98842073 | W4: =T4*V4 -> -4942103.7 | X4: =W4 -> -4942103.7 | Y4: =IF(U4>=0,A4,"") | Z4: =IF(X4>=0,A4,"")
A5: 2 | B5: =EDATE(Inputs!$B$8,A5-1) -> 46204 | C5: =ROUNDUP(A5/12,0) -> 1 | D5: =MOD(A5-1,12)+1 -> 2 | E5: =IF(A5<Inputs!$B$9,0,MIN(1,(A5-Inputs!$B$9+1)/Inputs!$I$32)) -> 0.33333333 | F5: =Inputs!$B$14*Inputs!$B$13*Inputs!$I$23 -> 280 | G5: =F5*Inputs!$B$12*E5 -> 533306.67 | H5: =INDEX(Inputs!$I$26:$K$26,1,C5) -> 3.9717498e+09 | I5: =INDEX(Inputs!$I$27:$K$27,1,C5) -> 0.07 | J5: =H5*Inputs!$B$18*I5/12*E5 -> 77228.469 | K5: =G5+J5 -> 610535.14 | L5: =IF(A5=1,Inputs!$I$29,0) -> 0 | M5: =IF(A5>=Inputs!$B$9,INDEX(Inputs!$I$30:$K$30,1,C5),0) -> 450000 | N5: =L5+M5 -> 450000 | O5: =K5-N5 -> 160535.14 | P5: =R4 -> 5000000 | Q5: =MAX(O5-P5,0) -> 0 | R5: =MAX(P5-O5,0) -> 4839464.9 | S5: =Q5*Inputs!$B$11 -> 0 | T5: =O5-S5 -> 160535.14 | U5: =U4+T5 -> -4839464.9 | V5: =1/(1+Inputs!$B$10)^(A5/12) -> 0.97697555 | W5: =T5*V5 -> 156838.9 | X5: =X4+W5 -> -4785264.8 | Y5: =IF(U5>=0,A5,"") | Z5: =IF(X5>=0,A5,"")
A6: 3 | B6: =EDATE(Inputs!$B$8,A6-1) -> 46235 | C6: =ROUNDUP(A6/12,0) -> 1 | D6: =MOD(A6-1,12)+1 -> 3 | E6: =IF(A6<Inputs!$B$9,0,MIN(1,(A6-Inputs!$B$9+1)/Inputs!$I$32)) -> 0.66666667 | F6: =Inputs!$B$14*Inputs!$B$13*Inputs!$I$23 -> 280 | G6: =F6*Inputs!$B$12*E6 -> 1066613.3 | H6: =INDEX(Inputs!$I$26:$K$26,1,C6) -> 3.9717498e+09 | I6: =INDEX(Inputs!$I$27:$K$27,1,C6) -> 0.07 | J6: =H6*Inputs!$B$18*I6/12*E6 -> 154456.94 | K6: =G6+J6 -> 1221070.3 | L6: =IF(A6=1,Inputs!$I$29,0) -> 0 | M6: =IF(A6>=Inputs!$B$9,INDEX(Inputs!$I$30:$K$30,1,C6),0) -> 450000 | N6: =L6+M6 -> 450000 | O6: =K6-N6 -> 771070.27 | P6: =R5 -> 4839464.9 | Q6: =MAX(O6-P6,0) -> 0 | R6: =MAX(P6-O6,0) -> 4068394.6 | S6: =Q6*Inputs!$B$11 -> 0 | T6: =O6-S6 -> 771070.27 | U6: =U5+T6 -> -4068394.6 | V6: =1/(1+Inputs!$B$10)^(A6/12) -> 0.96566289 | W6: =T6*V6 -> 744593.94 | X6: =X5+W6 -> -4040670.8 | Y6: =IF(U6>=0,A6,"") | Z6: =IF(X6>=0,A6,"")
A7: 4 | B7: =EDATE(Inputs!$B$8,A7-1) -> 46266 | C7: =ROUNDUP(A7/12,0) -> 1 | D7: =MOD(A7-1,12)+1 -> 4 | E7: =IF(A7<Inputs!$B$9,0,MIN(1,(A7-Inputs!$B$9+1)/Inputs!$I$32)) -> 1 | F7: =Inputs!$B$14*Inputs!$B$13*Inputs!$I$23 -> 280 | G7: =F7*Inputs!$B$12*E7 -> 1599920 | H7: =INDEX(Inputs!$I$26:$K$26,1,C7) -> 3.9717498e+09 | I7: =INDEX(Inputs!$I$27:$K$27,1,C7) -> 0.07 | J7: =H7*Inputs!$B$18*I7/12*E7 -> 231685.41 | K7: =G7+J7 -> 1831605.4 | L7: =IF(A7=1,Inputs!$I$29,0) -> 0 | M7: =IF(A7>=Inputs!$B$9,INDEX(Inputs!$I$30:$K$30,1,C7),0) -> 450000 | N7: =L7+M7 -> 450000 | O7: =K7-N7 -> 1381605.4 | P7: =R6 -> 4068394.6 | Q7: =MAX(O7-P7,0) -> 0 | R7: =MAX(P7-O7,0) -> 2686789.2 | S7: =Q7*Inputs!$B$11 -> 0 | T7: =O7-S7 -> 1381605.4 | U7: =U6+T7 -> -2686789.2 | V7: =1/(1+Inputs!$B$10)^(A7/12) -> 0.95448122 | W7: =T7*V7 -> 1318716.4 | X7: =X6+W7 -> -2721954.4 | Y7: =IF(U7>=0,A7,"") | Z7: =IF(X7>=0,A7,"")
A8: 5 | B8: =EDATE(Inputs!$B$8,A8-1) -> 46296 | C8: =ROUNDUP(A8/12,0) -> 1 | D8: =MOD(A8-1,12)+1 -> 5 | E8: =IF(A8<Inputs!$B$9,0,MIN(1,(A8-Inputs!$B$9+1)/Inputs!$I$32)) -> 1 | F8: =Inputs!$B$14*Inputs!$B$13*Inputs!$I$23 -> 280 | G8: =F8*Inputs!$B$12*E8 -> 1599920 | H8: =INDEX(Inputs!$I$26:$K$26,1,C8) -> 3.9717498e+09 | I8: =INDEX(Inputs!$I$27:$K$27,1,C8) -> 0.07 | J8: =H8*Inputs!$B$18*I8/12*E8 -> 231685.41 | K8: =G8+J8 -> 1831605.4 | L8: =IF(A8=1,Inputs!$I$29,0) -> 0 | M8: =IF(A8>=Inputs!$B$9,INDEX(Inputs!$I$30:$K$30,1,C8),0) -> 450000 | N8: =L8+M8 -> 450000 | O8: =K8-N8 -> 1381605.4 | P8: =R7 -> 2686789.2 | Q8: =MAX(O8-P8,0) -> 0 | R8: =MAX(P8-O8,0) -> 1305183.8 | S8: =Q8*Inputs!$B$11 -> 0 | T8: =O8-S8 -> 1381605.4 | U8: =U7+T8 -> -1305183.8 | V8: =1/(1+Inputs!$B$10)^(A8/12) -> 0.94342902 | W8: =T8*V8 -> 1303446.6 | X8: =X7+W8 -> -1418507.8 | Y8: =IF(U8>=0,A8,"") | Z8: =IF(X8>=0,A8,"")
A9: 6 | B9: =EDATE(Inputs!$B$8,A9-1) -> 46327 | C9: =ROUNDUP(A9/12,0) -> 1 | D9: =MOD(A9-1,12)+1 -> 6 | E9: =IF(A9<Inputs!$B$9,0,MIN(1,(A9-Inputs!$B$9+1)/Inputs!$I$32)) -> 1 | F9: =Inputs!$B$14*Inputs!$B$13*Inputs!$I$23 -> 280 | G9: =F9*Inputs!$B$12*E9 -> 1599920 | H9: =INDEX(Inputs!$I$26:$K$26,1,C9) -> 3.9717498e+09 | I9: =INDEX(Inputs!$I$27:$K$27,1,C9) -> 0.07 | J9: =H9*Inputs!$B$18*I9/12*E9 -> 231685.41 | K9: =G9+J9 -> 1831605.4 | L9: =IF(A9=1,Inputs!$I$29,0) -> 0 | M9: =IF(A9>=Inputs!$B$9,INDEX(Inputs!$I$30:$K$30,1,C9),0) -> 450000 | N9: =L9+M9 -> 450000 | O9: =K9-N9 -> 1381605.4 | P9: =R8 -> 1305183.8 | Q9: =MAX(O9-P9,0) -> 76421.626 | R9: =MAX(P9-O9,0) -> 0 | S9: =Q9*Inputs!$B$11 -> 15284.325 | T9: =O9-S9 -> 1366321.1 | U9: =U8+T9 -> 61137.301 | V9: =1/(1+Inputs!$B$10)^(A9/12) -> 0.93250481 | W9: =T9*V9 -> 1274101 | X9: =X8+W9 -> -144406.79 | Y9: =IF(U9>=0,A9,"") -> 6 | Z9: =IF(X9>=0,A9,"")
A10: 7 | B10: =EDATE(Inputs!$B$8,A10-1) -> 46357 | C10: =ROUNDUP(A10/12,0) -> 1 | D10: =MOD(A10-1,12)+1 -> 7 | E10: =IF(A10<Inputs!$B$9,0,MIN(1,(A10-Inputs!$B$9+1)/Inputs!$I$32)) -> 1 | F10: =Inputs!$B$14*Inputs!$B$13*Inputs!$I$23 -> 280 | G10: =F10*Inputs!$B$12*E10 -> 1599920 | H10: =INDEX(Inputs!$I$26:$K$26,1,C10) -> 3.9717498e+09 | I10: =INDEX(Inputs!$I$27:$K$27,1,C10) -> 0.07 | J10: =H10*Inputs!$B$18*I10/12*E10 -> 231685.41 | K10: =G10+J10 -> 1831605.4 | L10: =IF(A10=1,Inputs!$I$29,0) -> 0 | M10: =IF(A10>=Inputs!$B$9,INDEX(Inputs!$I$30:$K$30,1,C10),0) -> 450000 | N10: =L10+M10 -> 450000 | O10: =K10-N10 -> 1381605.4 | P10: =R9 -> 0 | Q10: =MAX(O10-P10,0) -> 1381605.4 | R10: =MAX(P10-O10,0) -> 0 | S10: =Q10*Inputs!$B$11 -> 276321.08 | T10: =O10-S10 -> 1105284.3 | U10: =U9+T10 -> 1166421.6 | V10: =1/(1+Inputs!$B$10)^(A10/12) -> 0.92170709 | W10: =T10*V10 -> 1018748.4 | X10: =X9+W10 -> 874341.6 | Y10: =IF(U10>=0,A10,"") -> 7 | Z10: =IF(X10>=0,A10,"") -> 7
A11: 8 | B11: =EDATE(Inputs!$B$8,A11-1) -> 46388 | C11: =ROUNDUP(A11/12,0) -> 1 | D11: =MOD(A11-1,12)+1 -> 8 | E11: =IF(A11<Inputs!$B$9,0,MIN(1,(A11-Inputs!$B$9+1)/Inputs!$I$32)) -> 1 | F11: =Inputs!$B$14*Inputs!$B$13*Inputs!$I$23 -> 280 | G11: =F11*Inputs!$B$12*E11 -> 1599920 | H11: =INDEX(Inputs!$I$26:$K$26,1,C11) -> 3.9717498e+09 | I11: =INDEX(Inputs!$I$27:$K$27,1,C11) -> 0.07 | J11: =H11*Inputs!$B$18*I11/12*E11 -> 231685.41 | K11: =G11+J11 -> 1831605.4 | L11: =IF(A11=1,Inputs!$I$29,0) -> 0 | M11: =IF(A11>=Inputs!$B$9,INDEX(Inputs!$I$30:$K$30,1,C11),0) -> 450000 | N11: =L11+M11 -> 450000 | O11: =K11-N11 -> 1381605.4 | P11: =R10 -> 0 | Q11: =MAX(O11-P11,0) -> 1381605.4 | R11: =MAX(P11-O11,0) -> 0 | S11: =Q11*Inputs!$B$11 -> 276321.08 | T11: =O11-S11 -> 1105284.3 | U11: =U10+T11 -> 2271706 | V11: =1/(1+Inputs!$B$10)^(A11/12) -> 0.91103439 | W11: =T11*V11 -> 1006952 | X11: =X10+W11 -> 1881293.6 | Y11: =IF(U11>=0,A11,"") -> 8 | Z11: =IF(X11>=0,A11,"") -> 8
A12: 9 | B12: =EDATE(Inputs!$B$8,A12-1) -> 46419 | C12: =ROUNDUP(A12/12,0) -> 1 | D12: =MOD(A12-1,12)+1 -> 9 | E12: =IF(A12<Inputs!$B$9,0,MIN(1,(A12-Inputs!$B$9+1)/Inputs!$I$32)) -> 1 | F12: =Inputs!$B$14*Inputs!$B$13*Inputs!$I$23 -> 280 | G12: =F12*Inputs!$B$12*E12 -> 1599920 | H12: =INDEX(Inputs!$I$26:$K$26,1,C12) -> 3.9717498e+09 | I12: =INDEX(Inputs!$I$27:$K$27,1,C12) -> 0.07 | J12: =H12*Inputs!$B$18*I12/12*E12 -> 231685.41 | K12: =G12+J12 -> 1831605.4 | L12: =IF(A12=1,Inputs!$I$29,0) -> 0 | M12: =IF(A12>=Inputs!$B$9,INDEX(Inputs!$I$30:$K$30,1,C12),0) -> 450000 | N12: =L12+M12 -> 450000 | O12: =K12-N12 -> 1381605.4 | P12: =R11 -> 0 | Q12: =MAX(O12-P12,0) -> 1381605.4 | R12: =MAX(P12-O12,0) -> 0 | S12: =Q12*Inputs!$B$11 -> 276321.08 | T12: =O12-S12 -> 1105284.3 | U12: =U11+T12 -> 3376990.3 | V12: =1/(1+Inputs!$B$10)^(A12/12) -> 0.90048528 | W12: =T12*V12 -> 995292.27 | X12: =X11+W12 -> 2876585.9 | Y12: =IF(U12>=0,A12,"") -> 9 | Z12: =IF(X12>=0,A12,"") -> 9
A13: 10 | B13: =EDATE(Inputs!$B$8,A13-1) -> 46447 | C13: =ROUNDUP(A13/12,0) -> 1 | D13: =MOD(A13-1,12)+1 -> 10 | E13: =IF(A13<Inputs!$B$9,0,MIN(1,(A13-Inputs!$B$9+1)/Inputs!$I$32)) -> 1 | F13: =Inputs!$B$14*Inputs!$B$13*Inputs!$I$23 -> 280 | G13: =F13*Inputs!$B$12*E13 -> 1599920 | H13: =INDEX(Inputs!$I$26:$K$26,1,C13) -> 3.9717498e+09 | I13: =INDEX(Inputs!$I$27:$K$27,1,C13) -> 0.07 | J13: =H13*Inputs!$B$18*I13/12*E13 -> 231685.41 | K13: =G13+J13 -> 1831605.4 | L13: =IF(A13=1,Inputs!$I$29,0) -> 0 | M13: =IF(A13>=Inputs!$B$9,INDEX(Inputs!$I$30:$K$30,1,C13),0) -> 450000 | N13: =L13+M13 -> 450000 | O13: =K13-N13 -> 1381605.4 | P13: =R12 -> 0 | Q13: =MAX(O13-P13,0) -> 1381605.4 | R13: =MAX(P13-O13,0) -> 0 | S13: =Q13*Inputs!$B$11 -> 276321.08 | T13: =O13-S13 -> 1105284.3 | U13: =U12+T13 -> 4482274.6 | V13: =1/(1+Inputs!$B$10)^(A13/12) -> 0.89005832 | W13: =T13*V13 -> 983767.51 | X13: =X12+W13 -> 3860353.4 | Y13: =IF(U13>=0,A13,"") -> 10 | Z13: =IF(X13>=0,A13,"") -> 10
A14: 11 | B14: =EDATE(Inputs!$B$8,A14-1) -> 46478 | C14: =ROUNDUP(A14/12,0) -> 1 | D14: =MOD(A14-1,12)+1 -> 11 | E14: =IF(A14<Inputs!$B$9,0,MIN(1,(A14-Inputs!$B$9+1)/Inputs!$I$32)) -> 1 | F14: =Inputs!$B$14*Inputs!$B$13*Inputs!$I$23 -> 280 | G14: =F14*Inputs!$B$12*E14 -> 1599920 | H14: =INDEX(Inputs!$I$26:$K$26,1,C14) -> 3.9717498e+09 | I14: =INDEX(Inputs!$I$27:$K$27,1,C14) -> 0.07 | J14: =H14*Inputs!$B$18*I14/12*E14 -> 231685.41 | K14: =G14+J14 -> 1831605.4 | L14: =IF(A14=1,Inputs!$I$29,0) -> 0 | M14: =IF(A14>=Inputs!$B$9,INDEX(Inputs!$I$30:$K$30,1,C14),0) -> 450000 | N14: =L14+M14 -> 450000 | O14: =K14-N14 -> 1381605.4 | P14: =R13 -> 0 | Q14: =MAX(O14-P14,0) -> 1381605.4 | R14: =MAX(P14-O14,0) -> 0 | S14: =Q14*Inputs!$B$11 -> 276321.08 | T14: =O14-S14 -> 1105284.3 | U14: =U13+T14 -> 5587558.9 | V14: =1/(1+Inputs!$B$10)^(A14/12) -> 0.8797521 | W14: =T14*V14 -> 972376.21 | X14: =X13+W14 -> 4832729.6 | Y14: =IF(U14>=0,A14,"") -> 11 | Z14: =IF(X14>=0,A14,"") -> 11
A15: 12 | B15: =EDATE(Inputs!$B$8,A15-1) -> 46508 | C15: =ROUNDUP(A15/12,0) -> 1 | D15: =MOD(A15-1,12)+1 -> 12 | E15: =IF(A15<Inputs!$B$9,0,MIN(1,(A15-Inputs!$B$9+1)/Inputs!$I$32)) -> 1 | F15: =Inputs!$B$14*Inputs!$B$13*Inputs!$I$23 -> 280 | G15: =F15*Inputs!$B$12*E15 -> 1599920 | H15: =INDEX(Inputs!$I$26:$K$26,1,C15) -> 3.9717498e+09 | I15: =INDEX(Inputs!$I$27:$K$27,1,C15) -> 0.07 | J15: =H15*Inputs!$B$18*I15/12*E15 -> 231685.41 | K15: =G15+J15 -> 1831605.4 | L15: =IF(A15=1,Inputs!$I$29,0) -> 0 | M15: =IF(A15>=Inputs!$B$9,INDEX(Inputs!$I$30:$K$30,1,C15),0) -> 450000 | N15: =L15+M15 -> 450000 | O15: =K15-N15 -> 1381605.4 | P15: =R14 -> 0 | Q15: =MAX(O15-P15,0) -> 1381605.4 | R15: =MAX(P15-O15,0) -> 0 | S15: =Q15*Inputs!$B$11 -> 276321.08 | T15: =O15-S15 -> 1105284.3 | U15: =U14+T15 -> 6692843.3 | V15: =1/(1+Inputs!$B$10)^(A15/12) -> 0.86956522 | W15: =T15*V15 -> 961116.8 | X15: =X14+W15 -> 5793846.4 | Y15: =IF(U15>=0,A15,"") -> 12 | Z15: =IF(X15>=0,A15,"") -> 12
A16: 13 | B16: =EDATE(Inputs!$B$8,A16-1) -> 46539 | C16: =ROUNDUP(A16/12,0) -> 2 | D16: =MOD(A16-1,12)+1 -> 1 | E16: =IF(A16<Inputs!$B$9,0,MIN(1,(A16-Inputs!$B$9+1)/Inputs!$I$32)) -> 1 | F16: =Inputs!$B$14*Inputs!$B$13*Inputs!$I$23 -> 280 | G16: =F16*Inputs!$B$12*E16 -> 1599920 | H16: =INDEX(Inputs!$I$26:$K$26,1,C16) -> 6.5533872e+09 | I16: =INDEX(Inputs!$I$27:$K$27,1,C16) -> 0.07 | J16: =H16*Inputs!$B$18*I16/12*E16 -> 382280.92 | K16: =G16+J16 -> 1982200.9 | L16: =IF(A16=1,Inputs!$I$29,0) -> 0 | M16: =IF(A16>=Inputs!$B$9,INDEX(Inputs!$I$30:$K$30,1,C16),0) -> 460000 | N16: =L16+M16 -> 460000 | O16: =K16-N16 -> 1522200.9 | P16: =R15 -> 0 | Q16: =MAX(O16-P16,0) -> 1522200.9 | R16: =MAX(P16-O16,0) -> 0 | S16: =Q16*Inputs!$B$11 -> 304440.18 | T16: =O16-S16 -> 1217760.7 | U16: =U15+T16 -> 7910604 | V16: =1/(1+Inputs!$B$10)^(A16/12) -> 0.85949629 | W16: =T16*V16 -> 1046660.8 | X16: =X15+W16 -> 6840507.3 | Y16: =IF(U16>=0,A16,"") -> 13 | Z16: =IF(X16>=0,A16,"") -> 13
... A39: 36 | B39: =EDATE(Inputs!$B$8,A39-1) -> 47239 | C39: =ROUNDUP(A39/12,0) -> 3 | D39: =MOD(A39-1,12)+1 -> 12 | E39: =IF(A39<Inputs!$B$9,0,MIN(1,(A39-Inputs!$B$9+1)/Inputs!$I$32)) -> 1 | F39: =Inputs!$B$14*Inputs!$B$13*Inputs!$I$23 -> 280 | G39: =F39*Inputs!$B$12*E39 -> 1599920 | H39: =INDEX(Inputs!$I$26:$K$26,1,C39) -> 1.0813089e+10 | I39: =INDEX(Inputs!$I$27:$K$27,1,C39) -> 0.07 | J39: =H39*Inputs!$B$18*I39/12*E39 -> 630763.52 | K39: =G39+J39 -> 2230683.5 | L39: =IF(A39=1,Inputs!$I$29,0) -> 0 | M39: =IF(A39>=Inputs!$B$9,INDEX(Inputs!$I$30:$K$30,1,C39),0) -> 480000 | N39: =L39+M39 -> 480000 | O39: =K39-N39 -> 1750683.5 | P39: =R38 -> 0 | Q39: =MAX(O39-P39,0) -> 1750683.5 | R39: =MAX(P39-O39,0) -> 0 | S39: =Q39*Inputs!$B$11 -> 350136.7 | T39: =O39-S39 -> 1400546.8 | U39: =U38+T39 -> 38112534 | V39: =1/(1+Inputs!$B$10)^(A39/12) -> 0.65751623 | W39: =T39*V39 -> 920882.27 | X39: =X38+W39 -> 29375119 | Y39: =IF(U39>=0,A39,"") -> 36 | Z39: =IF(X39>=0,A39,"") -> 36
A41: ИТОГИ ПО ГОДАМ И МЕТРИКИ ОКУПАЕМОСТИ
A42: Показатель | B42: Год 1 | C42: Год 2 | D42: Год 3 | E42: Итого / Значение
A43: Выгоды (экономия), ₸ | B43: =SUM(K4:K15) -> 18316054 | C43: =SUM(K16:K27) -> 23786411 | D43: =SUM(K28:K39) -> 26768202 | E43: =SUM(K4:K39) -> 68870667
A44: Затраты (разработка + опер.), ₸ | B44: =SUM(N4:N15) -> 9950000 | C44: =SUM(N16:N27) -> 5520000 | D44: =SUM(N28:N39) -> 5760000 | E44: =SUM(N4:N39) -> 21230000
A45: Прибыль до налога, ₸ | B45: =SUM(O4:O15) -> 8366054.1 | C45: =SUM(O16:O27) -> 18266411 | D45: =SUM(O28:O39) -> 21008202 | E45: =SUM(O4:O39) -> 47640667
A46: Налог (КПН), ₸ | B46: =SUM(S4:S15) -> 1673210.8 | C46: =SUM(S16:S27) -> 3653282.2 | D46: =SUM(S28:S39) -> 4201640.4 | E46: =SUM(S4:S39) -> 9528133.5
A47: Чистая выгода (после налога), ₸ | B47: =SUM(T4:T15) -> 6692843.3 | C47: =SUM(T16:T27) -> 14613129 | D47: =SUM(T28:T39) -> 16806562 | E47: =SUM(T4:T39) -> 38112534
A48: Накопл. чистая выгода, ₸ | B48: =U15 -> 6692843.3 | C48: =U27 -> 21305972 | D48: =U39 -> 38112534 | E48: =U39 -> 38112534
A50: NPV при ставке диск., ₸ | E50: =SUM(W4:W39) -> 29375119
A51: IRR (годовая) | E51: =IFERROR((1+IRR(T4:T39))^12-1,"n/a") -> 7.8630933
A52: Простая окупаемость, мес | E52: =IFERROR(SMALL(Y4:Y39,1),">36") -> 6
A53: Дисконт. окупаемость, мес | E53: =IFERROR(SMALL(Z4:Z39,1),">36") -> 7
A54: ROI за 3 года (чист.выгода/затраты) | E54: =E47/E44 -> 1.7952206
A55: PV выгод, ₸ | E55: =SUMPRODUCT(K4:K39,V4:V39) -> 54771634
A56: PV затрат, ₸ | E56: =SUMPRODUCT(N4:N39,V4:V39) -> 18002381
A57: Выгода / затраты (BCR) | E57: =E55/E56 -> 3.0424661

Sheet Annual_Summary
A1: Итоги по годам — активный сценарий
A2: ="Активный сценарий: "&Inputs!B4&" · денежные суммы в ₸ млн (кроме %, мес, x)" -> Активный сценарий: Реалистичный · денежные суммы в ₸ млн (кроме %, мес, x)
A3: Показатель | B3: Год 1 | C3: Год 2 | D3: Год 3 | E3: Итого / Значение
A4: Выгоды (экономия), ₸ млн | B4: =CHOOSE(Inputs!$B$5,Calc_Pess!B43,Calc_Base!B43,Calc_Opt!B43) -> 13135562 | C4: =CHOOSE(Inputs!$B$5,Calc_Pess!C43,Calc_Base!C43,Calc_Opt!C43) -> 19329646 | D4: =CHOOSE(Inputs!$B$5,Calc_Pess!D43,Calc_Base!D43,Calc_Opt!D43) -> 20468365 | E4: =CHOOSE(Inputs!$B$5,Calc_Pess!E43,Calc_Base!E43,Calc_Opt!E43) -> 52933573
A5: Затраты (разработка + опер.), ₸ млн | B5: =CHOOSE(Inputs!$B$5,Calc_Pess!B44,Calc_Base!B44,Calc_Opt!B44) -> 10500000 | C5: =CHOOSE(Inputs!$B$5,Calc_Pess!C44,Calc_Base!C44,Calc_Opt!C44) -> 6240000 | D5: =CHOOSE(Inputs!$B$5,Calc_Pess!D44,Calc_Base!D44,Calc_Opt!D44) -> 6600000 | E5: =CHOOSE(Inputs!$B$5,Calc_Pess!E44,Calc_Base!E44,Calc_Opt!E44) -> 23340000
A6: Прибыль до налога, ₸ млн | B6: =CHOOSE(Inputs!$B$5,Calc_Pess!B45,Calc_Base!B45,Calc_Opt!B45) -> 2635562 | C6: =CHOOSE(Inputs!$B$5,Calc_Pess!C45,Calc_Base!C45,Calc_Opt!C45) -> 13089646 | D6: =CHOOSE(Inputs!$B$5,Calc_Pess!D45,Calc_Base!D45,Calc_Opt!D45) -> 13868365 | E6: =CHOOSE(Inputs!$B$5,Calc_Pess!E45,Calc_Base!E45,Calc_Opt!E45) -> 29593573
A7: Налог (КПН), ₸ млн | B7: =CHOOSE(Inputs!$B$5,Calc_Pess!B46,Calc_Base!B46,Calc_Opt!B46) -> 527112.4 | C7: =CHOOSE(Inputs!$B$5,Calc_Pess!C46,Calc_Base!C46,Calc_Opt!C46) -> 2617929.2 | D7: =CHOOSE(Inputs!$B$5,Calc_Pess!D46,Calc_Base!D46,Calc_Opt!D46) -> 2773673 | E7: =CHOOSE(Inputs!$B$5,Calc_Pess!E46,Calc_Base!E46,Calc_Opt!E46) -> 5918714.6
A8: Чистая выгода (после налога), ₸ млн | B8: =CHOOSE(Inputs!$B$5,Calc_Pess!B47,Calc_Base!B47,Calc_Opt!B47) -> 2108449.6 | C8: =CHOOSE(Inputs!$B$5,Calc_Pess!C47,Calc_Base!C47,Calc_Opt!C47) -> 10471717 | D8: =CHOOSE(Inputs!$B$5,Calc_Pess!D47,Calc_Base!D47,Calc_Opt!D47) -> 11094692 | E8: =CHOOSE(Inputs!$B$5,Calc_Pess!E47,Calc_Base!E47,Calc_Opt!E47) -> 23674858
A9: Накопл. чистая выгода, ₸ млн | B9: =CHOOSE(Inputs!$B$5,Calc_Pess!B48,Calc_Base!B48,Calc_Opt!B48) -> 2108449.6 | C9: =CHOOSE(Inputs!$B$5,Calc_Pess!C48,Calc_Base!C48,Calc_Opt!C48) -> 12580166 | D9: =CHOOSE(Inputs!$B$5,Calc_Pess!D48,Calc_Base!D48,Calc_Opt!D48) -> 23674858 | E9: =CHOOSE(Inputs!$B$5,Calc_Pess!E48,Calc_Base!E48,Calc_Opt!E48) -> 23674858
A11: NPV при ставке диск., ₸ млн | E11: =CHOOSE(Inputs!$B$5,Calc_Pess!E50,Calc_Base!E50,Calc_Opt!E50) -> 17716938
A12: IRR (годовая) | E12: =CHOOSE(Inputs!$B$5,Calc_Pess!E51,Calc_Base!E51,Calc_Opt!E51) -> 2.9136048
A13: Простая окупаемость, мес | E13: =CHOOSE(Inputs!$B$5,Calc_Pess!E52,Calc_Base!E52,Calc_Opt!E52) -> 10
A14: Дисконт. окупаемость, мес | E14: =CHOOSE(Inputs!$B$5,Calc_Pess!E53,Calc_Base!E53,Calc_Opt!E53) -> 10
A15: ROI за 3 года (чист.выгода/затраты) | E15: =CHOOSE(Inputs!$B$5,Calc_Pess!E54,Calc_Base!E54,Calc_Opt!E54) -> 1.014347
A16: PV выгод, ₸ млн | E16: =CHOOSE(Inputs!$B$5,Calc_Pess!E55,Calc_Base!E55,Calc_Opt!E55) -> 41917703
A17: PV затрат, ₸ млн | E17: =CHOOSE(Inputs!$B$5,Calc_Pess!E56,Calc_Base!E56,Calc_Opt!E56) -> 19679899
A18: Выгода / затраты (BCR) | E18: =CHOOSE(Inputs!$B$5,Calc_Pess!E57,Calc_Base!E57,Calc_Opt!E57) -> 2.1299755

Sheet Scenario_Compare
A1: Сравнение сценариев — ключевые итоги за 3 года
A2: Все три сценария рассчитаны независимо. Активный выбирается на листе Inputs. Денежные суммы — в ₸ млн.
A3: Показатель | B3: Пессимистичный | C3: Реалистичный | D3: Оптимистичный
A4: Выгоды за 3 года, ₸ млн | B4: =Calc_Pess!E43 -> 40552704 | C4: =Calc_Base!E43 -> 52933573 | D4: =Calc_Opt!E43 -> 68870667
A5: Затраты за 3 года, ₸ млн | B5: =Calc_Pess!E44 -> 27560000 | C5: =Calc_Base!E44 -> 23340000 | D5: =Calc_Opt!E44 -> 21230000
A6: Налог за 3 года, ₸ млн | B6: =Calc_Pess!E46 -> 2598540.8 | C6: =Calc_Base!E46 -> 5918714.6 | D6: =Calc_Opt!E46 -> 9528133.5
A7: Чистая выгода за 3 года, ₸ млн | B7: =Calc_Pess!E47 -> 10394163 | C7: =Calc_Base!E47 -> 23674858 | D7: =Calc_Opt!E47 -> 38112534
A8: Чистая выгода Год 1, ₸ млн | B8: =Calc_Pess!B47 -> -2652799.9 | C8: =Calc_Base!B47 -> 2108449.6 | D8: =Calc_Opt!B47 -> 6692843.3
A9: Чистая выгода Год 2, ₸ млн | B9: =Calc_Pess!C47 -> 6882312.3 | C9: =Calc_Base!C47 -> 10471717 | D9: =Calc_Opt!C47 -> 14613129
A10: Чистая выгода Год 3, ₸ млн | B10: =Calc_Pess!D47 -> 6164650.8 | C10: =Calc_Base!D47 -> 11094692 | D10: =Calc_Opt!D47 -> 16806562
A11: NPV, ₸ млн | B11: =Calc_Pess!E50 -> 6973883.5 | C11: =Calc_Base!E50 -> 17716938 | D11: =Calc_Opt!E50 -> 29375119
A12: IRR (годовая) | B12: =Calc_Pess!E51 -> 0.96546688 | C12: =Calc_Base!E51 -> 2.9136048 | D12: =Calc_Opt!E51 -> 7.8630933
A13: Простая окупаемость, мес | B13: =Calc_Pess!E52 -> 17 | C13: =Calc_Base!E52 -> 10 | D13: =Calc_Opt!E52 -> 6
A14: Дисконт. окупаемость, мес | B14: =Calc_Pess!E53 -> 18 | C14: =Calc_Base!E53 -> 10 | D14: =Calc_Opt!E53 -> 7
A15: ROI за 3 года | B15: =Calc_Pess!E54 -> 0.3771467 | C15: =Calc_Base!E54 -> 1.014347 | D15: =Calc_Opt!E54 -> 1.7952206
A16: Выгода/затраты (BCR) | B16: =Calc_Pess!E57 -> 1.3858567 | C16: =Calc_Base!E57 -> 2.1299755 | D16: =Calc_Opt!E57 -> 3.0424661

Sheet Dashboard
A1: Promo Automation — дашборд бизнес-кейса
